[2021-04-20T15:29:17+0800] [WARNING] [root] [pid:78131] [middleware.py:81] Traceback (most recent call last):
  File "/Users/xiezhaorong/Desktop/my_py/djmyframework/venv/lib/python3.7/site-packages/django/core/handlers/base.py", line 113, in _get_response
    response = wrapped_callback(request, *callback_args, **callback_kwargs)
  File "/Users/xiezhaorong/Desktop/my_py/djmyframework/venv/lib/python3.7/site-packages/django/views/decorators/csrf.py", line 54, in wrapped_view
    return view_func(*args, **kwargs)
  File "/Users/xiezhaorong/Desktop/my_py/djmyframework/venv/lib/python3.7/site-packages/rest_framework/viewsets.py", line 125, in view
    return self.dispatch(request, *args, **kwargs)
  File "/Users/xiezhaorong/Desktop/my_py/djmyframework/venv/lib/python3.7/site-packages/rest_framework/views.py", line 509, in dispatch
    response = self.handle_exception(exc)
  File "/Users/xiezhaorong/Desktop/my_py/djmyframework/venv/lib/python3.7/site-packages/rest_framework/views.py", line 469, in handle_exception
    self.raise_uncaught_exception(exc)
  File "/Users/xiezhaorong/Desktop/my_py/djmyframework/venv/lib/python3.7/site-packages/rest_framework/views.py", line 480, in raise_uncaught_exception
    raise exc
  File "/Users/xiezhaorong/Desktop/my_py/djmyframework/venv/lib/python3.7/site-packages/rest_framework/views.py", line 506, in dispatch
    response = handler(request, *args, **kwargs)
  File "/Users/xiezhaorong/Desktop/my_py/djmyframework/djmyframework/apps/log_def/views/log_define.py", line 60, in edit
    model_instance = LogDefine.objects.get(key=params.log_key)
  File "/Users/xiezhaorong/Desktop/my_py/djmyframework/venv/lib/python3.7/site-packages/django/db/models/manager.py", line 82, in manager_method
    return getattr(self.get_queryset(), name)(*args, **kwargs)
  File "/Users/xiezhaorong/Desktop/my_py/djmyframework/venv/lib/python3.7/site-packages/django/db/models/query.py", line 417, in get
    self.model._meta.object_name
log_def.models.LogDefine.DoesNotExist: LogDefine matching query does not exist.

[2021-04-20T15:29:17+0800] [ERROR] [django.request] [pid:78131] [log.py:228] Internal Server Error: /log_def/log_define/edit
Traceback (most recent call last):
  File "/Users/xiezhaorong/Desktop/my_py/djmyframework/venv/lib/python3.7/site-packages/django/core/handlers/exception.py", line 34, in inner
    response = get_response(request)
  File "/Users/xiezhaorong/Desktop/my_py/djmyframework/venv/lib/python3.7/site-packages/django/core/handlers/base.py", line 115, in _get_response
    response = self.process_exception_by_middleware(e, request)
  File "/Users/xiezhaorong/Desktop/my_py/djmyframework/venv/lib/python3.7/site-packages/django/core/handlers/base.py", line 113, in _get_response
    response = wrapped_callback(request, *callback_args, **callback_kwargs)
  File "/Users/xiezhaorong/Desktop/my_py/djmyframework/venv/lib/python3.7/site-packages/django/views/decorators/csrf.py", line 54, in wrapped_view
    return view_func(*args, **kwargs)
  File "/Users/xiezhaorong/Desktop/my_py/djmyframework/venv/lib/python3.7/site-packages/rest_framework/viewsets.py", line 125, in view
    return self.dispatch(request, *args, **kwargs)
  File "/Users/xiezhaorong/Desktop/my_py/djmyframework/venv/lib/python3.7/site-packages/rest_framework/views.py", line 509, in dispatch
    response = self.handle_exception(exc)
  File "/Users/xiezhaorong/Desktop/my_py/djmyframework/venv/lib/python3.7/site-packages/rest_framework/views.py", line 469, in handle_exception
    self.raise_uncaught_exception(exc)
  File "/Users/xiezhaorong/Desktop/my_py/djmyframework/venv/lib/python3.7/site-packages/rest_framework/views.py", line 480, in raise_uncaught_exception
    raise exc
  File "/Users/xiezhaorong/Desktop/my_py/djmyframework/venv/lib/python3.7/site-packages/rest_framework/views.py", line 506, in dispatch
    response = handler(request, *args, **kwargs)
  File "/Users/xiezhaorong/Desktop/my_py/djmyframework/djmyframework/apps/log_def/views/log_define.py", line 60, in edit
    model_instance = LogDefine.objects.get(key=params.log_key)
  File "/Users/xiezhaorong/Desktop/my_py/djmyframework/venv/lib/python3.7/site-packages/django/db/models/manager.py", line 82, in manager_method
    return getattr(self.get_queryset(), name)(*args, **kwargs)
  File "/Users/xiezhaorong/Desktop/my_py/djmyframework/venv/lib/python3.7/site-packages/django/db/models/query.py", line 417, in get
    self.model._meta.object_name
log_def.models.LogDefine.DoesNotExist: LogDefine matching query does not exist.
[2021-04-20T16:08:18+0800] [WARNING] [root] [pid:78907] [middleware.py:81] Traceback (most recent call last):
  File "/Users/xiezhaorong/Desktop/my_py/djmyframework/venv/lib/python3.7/site-packages/django/db/backends/utils.py", line 86, in _execute
    return self.cursor.execute(sql, params)
  File "/Users/xiezhaorong/Desktop/my_py/djmyframework/venv/lib/python3.7/site-packages/django/db/backends/sqlite3/base.py", line 396, in execute
    return Database.Cursor.execute(self, query, params)
sqlite3.OperationalError: no such column: sync_model_syncmodel.is_old

The above exception was the direct cause of the following exception:

Traceback (most recent call last):
  File "/Users/xiezhaorong/Desktop/my_py/djmyframework/venv/lib/python3.7/site-packages/django/core/handlers/base.py", line 113, in _get_response
    response = wrapped_callback(request, *callback_args, **callback_kwargs)
  File "/Users/xiezhaorong/Desktop/my_py/djmyframework/djmyframework/apps/sync_model/views.py", line 97, in backstage_list
    return render(request, "sync_model/sync_backstage_list.html", results)
  File "/Users/xiezhaorong/Desktop/my_py/djmyframework/venv/lib/python3.7/site-packages/django/shortcuts.py", line 19, in render
    content = loader.render_to_string(template_name, context, request, using=using)
  File "/Users/xiezhaorong/Desktop/my_py/djmyframework/venv/lib/python3.7/site-packages/django/template/loader.py", line 62, in render_to_string
    return template.render(context, request)
  File "/Users/xiezhaorong/Desktop/my_py/djmyframework/venv/lib/python3.7/site-packages/django/template/backends/jinja2.py", line 71, in render
    return self.template.render(context)
  File "/Users/xiezhaorong/Desktop/my_py/djmyframework/venv/lib/python3.7/site-packages/jinja2/environment.py", line 1090, in render
    self.environment.handle_exception()
  File "/Users/xiezhaorong/Desktop/my_py/djmyframework/venv/lib/python3.7/site-packages/jinja2/environment.py", line 832, in handle_exception
    reraise(*rewrite_traceback_stack(source=source))
  File "/Users/xiezhaorong/Desktop/my_py/djmyframework/venv/lib/python3.7/site-packages/jinja2/_compat.py", line 28, in reraise
    raise value.with_traceback(tb)
  File "/Users/xiezhaorong/Desktop/my_py/djmyframework/djmyframework/jinja2_templates/sync_model/sync_backstage_list.html", line 1, in top-level template code
    {% extends "framework/base.html" %}
  File "/Users/xiezhaorong/Desktop/my_py/djmyframework/djmyframework/jinja2_templates/framework/base.html", line 56, in top-level template code
    {% block content %}
  File "/Users/xiezhaorong/Desktop/my_py/djmyframework/djmyframework/jinja2_templates/sync_model/sync_backstage_list.html", line 58, in block "content"
    {% for serv in serv_list %}
  File "/Users/xiezhaorong/Desktop/my_py/djmyframework/venv/lib/python3.7/site-packages/django/db/models/query.py", line 276, in __iter__
    self._fetch_all()
  File "/Users/xiezhaorong/Desktop/my_py/djmyframework/venv/lib/python3.7/site-packages/django/db/models/query.py", line 1261, in _fetch_all
    self._result_cache = list(self._iterable_class(self))
  File "/Users/xiezhaorong/Desktop/my_py/djmyframework/venv/lib/python3.7/site-packages/django/db/models/query.py", line 115, in __iter__
    for row in compiler.results_iter(chunked_fetch=self.chunked_fetch, chunk_size=self.chunk_size):
  File "/Users/xiezhaorong/Desktop/my_py/djmyframework/venv/lib/python3.7/site-packages/django/db/models/sql/compiler.py", line 1106, in results_iter
    results = self.execute_sql(MULTI, chunked_fetch=chunked_fetch, chunk_size=chunk_size)
  File "/Users/xiezhaorong/Desktop/my_py/djmyframework/venv/lib/python3.7/site-packages/django/db/models/sql/compiler.py", line 1154, in execute_sql
    cursor.execute(sql, params)
  File "/Users/xiezhaorong/Desktop/my_py/djmyframework/venv/lib/python3.7/site-packages/django/db/backends/utils.py", line 100, in execute
    return super().execute(sql, params)
  File "/Users/xiezhaorong/Desktop/my_py/djmyframework/venv/lib/python3.7/site-packages/django/db/backends/utils.py", line 68, in execute
    return self._execute_with_wrappers(sql, params, many=False, executor=self._execute)
  File "/Users/xiezhaorong/Desktop/my_py/djmyframework/venv/lib/python3.7/site-packages/django/db/backends/utils.py", line 77, in _execute_with_wrappers
    return executor(sql, params, many, context)
  File "/Users/xiezhaorong/Desktop/my_py/djmyframework/venv/lib/python3.7/site-packages/django/db/backends/utils.py", line 86, in _execute
    return self.cursor.execute(sql, params)
  File "/Users/xiezhaorong/Desktop/my_py/djmyframework/venv/lib/python3.7/site-packages/django/db/utils.py", line 90, in __exit__
    raise dj_exc_value.with_traceback(traceback) from exc_value
  File "/Users/xiezhaorong/Desktop/my_py/djmyframework/venv/lib/python3.7/site-packages/django/db/backends/utils.py", line 86, in _execute
    return self.cursor.execute(sql, params)
  File "/Users/xiezhaorong/Desktop/my_py/djmyframework/venv/lib/python3.7/site-packages/django/db/backends/sqlite3/base.py", line 396, in execute
    return Database.Cursor.execute(self, query, params)
django.db.utils.OperationalError: no such column: sync_model_syncmodel.is_old

[2021-04-20T16:08:18+0800] [ERROR] [django.request] [pid:78907] [log.py:228] Internal Server Error: /sync/backstage/list
Traceback (most recent call last):
  File "/Users/xiezhaorong/Desktop/my_py/djmyframework/venv/lib/python3.7/site-packages/django/db/backends/utils.py", line 86, in _execute
    return self.cursor.execute(sql, params)
  File "/Users/xiezhaorong/Desktop/my_py/djmyframework/venv/lib/python3.7/site-packages/django/db/backends/sqlite3/base.py", line 396, in execute
    return Database.Cursor.execute(self, query, params)
sqlite3.OperationalError: no such column: sync_model_syncmodel.is_old

The above exception was the direct cause of the following exception:

Traceback (most recent call last):
  File "/Users/xiezhaorong/Desktop/my_py/djmyframework/venv/lib/python3.7/site-packages/django/core/handlers/exception.py", line 34, in inner
    response = get_response(request)
  File "/Users/xiezhaorong/Desktop/my_py/djmyframework/venv/lib/python3.7/site-packages/django/core/handlers/base.py", line 115, in _get_response
    response = self.process_exception_by_middleware(e, request)
  File "/Users/xiezhaorong/Desktop/my_py/djmyframework/venv/lib/python3.7/site-packages/django/core/handlers/base.py", line 113, in _get_response
    response = wrapped_callback(request, *callback_args, **callback_kwargs)
  File "/Users/xiezhaorong/Desktop/my_py/djmyframework/djmyframework/apps/sync_model/views.py", line 97, in backstage_list
    return render(request, "sync_model/sync_backstage_list.html", results)
  File "/Users/xiezhaorong/Desktop/my_py/djmyframework/venv/lib/python3.7/site-packages/django/shortcuts.py", line 19, in render
    content = loader.render_to_string(template_name, context, request, using=using)
  File "/Users/xiezhaorong/Desktop/my_py/djmyframework/venv/lib/python3.7/site-packages/django/template/loader.py", line 62, in render_to_string
    return template.render(context, request)
  File "/Users/xiezhaorong/Desktop/my_py/djmyframework/venv/lib/python3.7/site-packages/django/template/backends/jinja2.py", line 71, in render
    return self.template.render(context)
  File "/Users/xiezhaorong/Desktop/my_py/djmyframework/venv/lib/python3.7/site-packages/jinja2/environment.py", line 1090, in render
    self.environment.handle_exception()
  File "/Users/xiezhaorong/Desktop/my_py/djmyframework/venv/lib/python3.7/site-packages/jinja2/environment.py", line 832, in handle_exception
    reraise(*rewrite_traceback_stack(source=source))
  File "/Users/xiezhaorong/Desktop/my_py/djmyframework/venv/lib/python3.7/site-packages/jinja2/_compat.py", line 28, in reraise
    raise value.with_traceback(tb)
  File "/Users/xiezhaorong/Desktop/my_py/djmyframework/djmyframework/jinja2_templates/sync_model/sync_backstage_list.html", line 1, in top-level template code
    {% extends "framework/base.html" %}
  File "/Users/xiezhaorong/Desktop/my_py/djmyframework/djmyframework/jinja2_templates/framework/base.html", line 56, in top-level template code
    {% block content %}
  File "/Users/xiezhaorong/Desktop/my_py/djmyframework/djmyframework/jinja2_templates/sync_model/sync_backstage_list.html", line 58, in block "content"
    {% for serv in serv_list %}
  File "/Users/xiezhaorong/Desktop/my_py/djmyframework/venv/lib/python3.7/site-packages/django/db/models/query.py", line 276, in __iter__
    self._fetch_all()
  File "/Users/xiezhaorong/Desktop/my_py/djmyframework/venv/lib/python3.7/site-packages/django/db/models/query.py", line 1261, in _fetch_all
    self._result_cache = list(self._iterable_class(self))
  File "/Users/xiezhaorong/Desktop/my_py/djmyframework/venv/lib/python3.7/site-packages/django/db/models/query.py", line 115, in __iter__
    for row in compiler.results_iter(chunked_fetch=self.chunked_fetch, chunk_size=self.chunk_size):
  File "/Users/xiezhaorong/Desktop/my_py/djmyframework/venv/lib/python3.7/site-packages/django/db/models/sql/compiler.py", line 1106, in results_iter
    results = self.execute_sql(MULTI, chunked_fetch=chunked_fetch, chunk_size=chunk_size)
  File "/Users/xiezhaorong/Desktop/my_py/djmyframework/venv/lib/python3.7/site-packages/django/db/models/sql/compiler.py", line 1154, in execute_sql
    cursor.execute(sql, params)
  File "/Users/xiezhaorong/Desktop/my_py/djmyframework/venv/lib/python3.7/site-packages/django/db/backends/utils.py", line 100, in execute
    return super().execute(sql, params)
  File "/Users/xiezhaorong/Desktop/my_py/djmyframework/venv/lib/python3.7/site-packages/django/db/backends/utils.py", line 68, in execute
    return self._execute_with_wrappers(sql, params, many=False, executor=self._execute)
  File "/Users/xiezhaorong/Desktop/my_py/djmyframework/venv/lib/python3.7/site-packages/django/db/backends/utils.py", line 77, in _execute_with_wrappers
    return executor(sql, params, many, context)
  File "/Users/xiezhaorong/Desktop/my_py/djmyframework/venv/lib/python3.7/site-packages/django/db/backends/utils.py", line 86, in _execute
    return self.cursor.execute(sql, params)
  File "/Users/xiezhaorong/Desktop/my_py/djmyframework/venv/lib/python3.7/site-packages/django/db/utils.py", line 90, in __exit__
    raise dj_exc_value.with_traceback(traceback) from exc_value
  File "/Users/xiezhaorong/Desktop/my_py/djmyframework/venv/lib/python3.7/site-packages/django/db/backends/utils.py", line 86, in _execute
    return self.cursor.execute(sql, params)
  File "/Users/xiezhaorong/Desktop/my_py/djmyframework/venv/lib/python3.7/site-packages/django/db/backends/sqlite3/base.py", line 396, in execute
    return Database.Cursor.execute(self, query, params)
django.db.utils.OperationalError: no such column: sync_model_syncmodel.is_old
[2021-04-20T16:17:36+0800] [WARNING] [root] [pid:79075] [middleware.py:81] Traceback (most recent call last):
  File "/Users/xiezhaorong/Desktop/my_py/djmyframework/venv/lib/python3.7/site-packages/django/core/handlers/base.py", line 113, in _get_response
    response = wrapped_callback(request, *callback_args, **callback_kwargs)
  File "/Users/xiezhaorong/Desktop/my_py/djmyframework/djmyframework/apps/sync_model/views.py", line 118, in backstage_edit
    model.save()
  File "/Users/xiezhaorong/Desktop/my_py/djmyframework/venv/lib/python3.7/site-packages/django/db/models/base.py", line 749, in save
    force_update=force_update, update_fields=update_fields)
  File "/Users/xiezhaorong/Desktop/my_py/djmyframework/venv/lib/python3.7/site-packages/django/db/models/base.py", line 787, in save_base
    force_update, using, update_fields,
  File "/Users/xiezhaorong/Desktop/my_py/djmyframework/venv/lib/python3.7/site-packages/django/db/models/base.py", line 868, in _save_table
    forced_update)
  File "/Users/xiezhaorong/Desktop/my_py/djmyframework/venv/lib/python3.7/site-packages/django/db/models/base.py", line 920, in _do_update
    return filtered._update(values) > 0
  File "/Users/xiezhaorong/Desktop/my_py/djmyframework/venv/lib/python3.7/site-packages/django/db/models/query.py", line 771, in _update
    return query.get_compiler(self.db).execute_sql(CURSOR)
  File "/Users/xiezhaorong/Desktop/my_py/djmyframework/venv/lib/python3.7/site-packages/django/db/models/sql/compiler.py", line 1502, in execute_sql
    cursor = super().execute_sql(result_type)
  File "/Users/xiezhaorong/Desktop/my_py/djmyframework/venv/lib/python3.7/site-packages/django/db/models/sql/compiler.py", line 1141, in execute_sql
    sql, params = self.as_sql()
  File "/Users/xiezhaorong/Desktop/my_py/djmyframework/venv/lib/python3.7/site-packages/django/db/models/sql/compiler.py", line 1468, in as_sql
    val = field.get_db_prep_save(val, connection=self.connection)
  File "/Users/xiezhaorong/Desktop/my_py/djmyframework/venv/lib/python3.7/site-packages/django/db/models/fields/__init__.py", line 821, in get_db_prep_save
    return self.get_db_prep_value(value, connection=connection, prepared=False)
  File "/Users/xiezhaorong/Desktop/my_py/djmyframework/venv/lib/python3.7/site-packages/django/db/models/fields/__init__.py", line 816, in get_db_prep_value
    value = self.get_prep_value(value)
  File "/Users/xiezhaorong/Desktop/my_py/djmyframework/venv/lib/python3.7/site-packages/django/db/models/fields/__init__.py", line 965, in get_prep_value
    return self.to_python(value)
  File "/Users/xiezhaorong/Desktop/my_py/djmyframework/venv/lib/python3.7/site-packages/django/db/models/fields/__init__.py", line 958, in to_python
    params={'value': value},
django.core.exceptions.ValidationError: ['“true” value must be either True or False.']

[2021-04-20T16:17:37+0800] [ERROR] [django.request] [pid:79075] [log.py:228] Internal Server Error: /sync/backstage/edit
Traceback (most recent call last):
  File "/Users/xiezhaorong/Desktop/my_py/djmyframework/venv/lib/python3.7/site-packages/django/core/handlers/exception.py", line 34, in inner
    response = get_response(request)
  File "/Users/xiezhaorong/Desktop/my_py/djmyframework/venv/lib/python3.7/site-packages/django/core/handlers/base.py", line 115, in _get_response
    response = self.process_exception_by_middleware(e, request)
  File "/Users/xiezhaorong/Desktop/my_py/djmyframework/venv/lib/python3.7/site-packages/django/core/handlers/base.py", line 113, in _get_response
    response = wrapped_callback(request, *callback_args, **callback_kwargs)
  File "/Users/xiezhaorong/Desktop/my_py/djmyframework/djmyframework/apps/sync_model/views.py", line 118, in backstage_edit
    model.save()
  File "/Users/xiezhaorong/Desktop/my_py/djmyframework/venv/lib/python3.7/site-packages/django/db/models/base.py", line 749, in save
    force_update=force_update, update_fields=update_fields)
  File "/Users/xiezhaorong/Desktop/my_py/djmyframework/venv/lib/python3.7/site-packages/django/db/models/base.py", line 787, in save_base
    force_update, using, update_fields,
  File "/Users/xiezhaorong/Desktop/my_py/djmyframework/venv/lib/python3.7/site-packages/django/db/models/base.py", line 868, in _save_table
    forced_update)
  File "/Users/xiezhaorong/Desktop/my_py/djmyframework/venv/lib/python3.7/site-packages/django/db/models/base.py", line 920, in _do_update
    return filtered._update(values) > 0
  File "/Users/xiezhaorong/Desktop/my_py/djmyframework/venv/lib/python3.7/site-packages/django/db/models/query.py", line 771, in _update
    return query.get_compiler(self.db).execute_sql(CURSOR)
  File "/Users/xiezhaorong/Desktop/my_py/djmyframework/venv/lib/python3.7/site-packages/django/db/models/sql/compiler.py", line 1502, in execute_sql
    cursor = super().execute_sql(result_type)
  File "/Users/xiezhaorong/Desktop/my_py/djmyframework/venv/lib/python3.7/site-packages/django/db/models/sql/compiler.py", line 1141, in execute_sql
    sql, params = self.as_sql()
  File "/Users/xiezhaorong/Desktop/my_py/djmyframework/venv/lib/python3.7/site-packages/django/db/models/sql/compiler.py", line 1468, in as_sql
    val = field.get_db_prep_save(val, connection=self.connection)
  File "/Users/xiezhaorong/Desktop/my_py/djmyframework/venv/lib/python3.7/site-packages/django/db/models/fields/__init__.py", line 821, in get_db_prep_save
    return self.get_db_prep_value(value, connection=connection, prepared=False)
  File "/Users/xiezhaorong/Desktop/my_py/djmyframework/venv/lib/python3.7/site-packages/django/db/models/fields/__init__.py", line 816, in get_db_prep_value
    value = self.get_prep_value(value)
  File "/Users/xiezhaorong/Desktop/my_py/djmyframework/venv/lib/python3.7/site-packages/django/db/models/fields/__init__.py", line 965, in get_prep_value
    return self.to_python(value)
  File "/Users/xiezhaorong/Desktop/my_py/djmyframework/venv/lib/python3.7/site-packages/django/db/models/fields/__init__.py", line 958, in to_python
    params={'value': value},
django.core.exceptions.ValidationError: ['“true” value must be either True or False.']
[2021-04-20T16:21:23+0800] [WARNING] [root] [pid:79115] [middleware.py:81] Traceback (most recent call last):
  File "/Users/xiezhaorong/Desktop/my_py/djmyframework/venv/lib/python3.7/site-packages/django/core/handlers/base.py", line 113, in _get_response
    response = wrapped_callback(request, *callback_args, **callback_kwargs)
  File "/Users/xiezhaorong/Desktop/my_py/djmyframework/djmyframework/apps/sync_model/views.py", line 75, in backstage_list
    model = get_model_class(model_id)
  File "/Users/xiezhaorong/Desktop/my_py/djmyframework/djmyframework/apps/sync_model/views.py", line 41, in get_model_class
    return import_module_attr(model_id)
  File "/Users/xiezhaorong/Desktop/my_py/djmyframework/djmyframework/framework/utils/__init__.py", line 86, in import_func
    module, func = name.rsplit('.', 1)
ValueError: not enough values to unpack (expected 2, got 1)

[2021-04-20T16:21:24+0800] [ERROR] [django.request] [pid:79115] [log.py:228] Internal Server Error: /sync/backstage/list
Traceback (most recent call last):
  File "/Users/xiezhaorong/Desktop/my_py/djmyframework/venv/lib/python3.7/site-packages/django/core/handlers/exception.py", line 34, in inner
    response = get_response(request)
  File "/Users/xiezhaorong/Desktop/my_py/djmyframework/venv/lib/python3.7/site-packages/django/core/handlers/base.py", line 115, in _get_response
    response = self.process_exception_by_middleware(e, request)
  File "/Users/xiezhaorong/Desktop/my_py/djmyframework/venv/lib/python3.7/site-packages/django/core/handlers/base.py", line 113, in _get_response
    response = wrapped_callback(request, *callback_args, **callback_kwargs)
  File "/Users/xiezhaorong/Desktop/my_py/djmyframework/djmyframework/apps/sync_model/views.py", line 75, in backstage_list
    model = get_model_class(model_id)
  File "/Users/xiezhaorong/Desktop/my_py/djmyframework/djmyframework/apps/sync_model/views.py", line 41, in get_model_class
    return import_module_attr(model_id)
  File "/Users/xiezhaorong/Desktop/my_py/djmyframework/djmyframework/framework/utils/__init__.py", line 86, in import_func
    module, func = name.rsplit('.', 1)
ValueError: not enough values to unpack (expected 2, got 1)
[2021-04-20T16:27:18+0800] [WARNING] [root] [pid:79222] [middleware.py:81] Traceback (most recent call last):
  File "/Users/xiezhaorong/Desktop/my_py/djmyframework/venv/lib/python3.7/site-packages/django/core/handlers/base.py", line 113, in _get_response
    response = wrapped_callback(request, *callback_args, **callback_kwargs)
  File "/Users/xiezhaorong/Desktop/my_py/djmyframework/djmyframework/apps/sync_model/views.py", line 158, in backstage_push
    deserialize_data = json.loads(serialize_data)
  File "/Library/Frameworks/Python.framework/Versions/3.7/lib/python3.7/json/__init__.py", line 348, in loads
    return _default_decoder.decode(s)
  File "/Library/Frameworks/Python.framework/Versions/3.7/lib/python3.7/json/decoder.py", line 337, in decode
    obj, end = self.raw_decode(s, idx=_w(s, 0).end())
  File "/Library/Frameworks/Python.framework/Versions/3.7/lib/python3.7/json/decoder.py", line 355, in raw_decode
    raise JSONDecodeError("Expecting value", s, err.value) from None
json.decoder.JSONDecodeError: Expecting value: line 1 column 2 (char 1)

[2021-04-20T16:27:18+0800] [ERROR] [django.request] [pid:79222] [log.py:228] Internal Server Error: /sync/backstage/push
[2021-04-20T16:31:45+0800] [WARNING] [root] [pid:79288] [middleware.py:81] Traceback (most recent call last):
  File "/Users/xiezhaorong/Desktop/my_py/djmyframework/venv/lib/python3.7/site-packages/django/core/handlers/base.py", line 113, in _get_response
    response = wrapped_callback(request, *callback_args, **callback_kwargs)
  File "/Users/xiezhaorong/Desktop/my_py/djmyframework/djmyframework/apps/analysis/views/query.py", line 232, in query_view
    return render(request,template, locals())
  File "/Users/xiezhaorong/Desktop/my_py/djmyframework/venv/lib/python3.7/site-packages/django/shortcuts.py", line 19, in render
    content = loader.render_to_string(template_name, context, request, using=using)
  File "/Users/xiezhaorong/Desktop/my_py/djmyframework/venv/lib/python3.7/site-packages/django/template/loader.py", line 62, in render_to_string
    return template.render(context, request)
  File "/Users/xiezhaorong/Desktop/my_py/djmyframework/venv/lib/python3.7/site-packages/django/template/backends/jinja2.py", line 71, in render
    return self.template.render(context)
  File "/Users/xiezhaorong/Desktop/my_py/djmyframework/venv/lib/python3.7/site-packages/jinja2/environment.py", line 1090, in render
    self.environment.handle_exception()
  File "/Users/xiezhaorong/Desktop/my_py/djmyframework/venv/lib/python3.7/site-packages/jinja2/environment.py", line 832, in handle_exception
    reraise(*rewrite_traceback_stack(source=source))
  File "/Users/xiezhaorong/Desktop/my_py/djmyframework/venv/lib/python3.7/site-packages/jinja2/_compat.py", line 28, in reraise
    raise value.with_traceback(tb)
  File "/Users/xiezhaorong/Desktop/my_py/djmyframework/djmyframework/jinja2_templates/analysis/query_view.html", line 1, in top-level template code
    {% extends "analysis/base.html" %}
  File "/Users/xiezhaorong/Desktop/my_py/djmyframework/djmyframework/jinja2_templates/analysis/base.html", line 1, in top-level template code
    {% extends "framework/base.html" %}
  File "/Users/xiezhaorong/Desktop/my_py/djmyframework/djmyframework/jinja2_templates/framework/base.html", line 56, in top-level template code
    {% block content %}
  File "/Users/xiezhaorong/Desktop/my_py/djmyframework/djmyframework/jinja2_templates/analysis/query_view.html", line 151, in block "content"
    {% if condition_config and condition_config.get('template') %}
  File "/Users/xiezhaorong/Desktop/my_py/djmyframework/djmyframework/apps/analysis/models/query.py", line 222, in get_context_func
    return import_func(self.mark_map[mark_name]['context_func'])
  File "/Users/xiezhaorong/Desktop/my_py/djmyframework/djmyframework/framework/utils/__init__.py", line 87, in import_func
    return getattr(import_module(module), func)
  File "/Users/xiezhaorong/Desktop/my_py/djmyframework/djmyframework/framework/utils/__init__.py", line 82, in import_module
    return _import_module(name)
  File "/Library/Frameworks/Python.framework/Versions/3.7/lib/python3.7/importlib/__init__.py", line 127, in import_module
    return _bootstrap._gcd_import(name[level:], package, level)
  File "<frozen importlib._bootstrap>", line 1006, in _gcd_import
  File "<frozen importlib._bootstrap>", line 983, in _find_and_load
  File "<frozen importlib._bootstrap>", line 953, in _find_and_load_unlocked
  File "<frozen importlib._bootstrap>", line 219, in _call_with_frames_removed
  File "<frozen importlib._bootstrap>", line 1006, in _gcd_import
  File "<frozen importlib._bootstrap>", line 983, in _find_and_load
  File "<frozen importlib._bootstrap>", line 953, in _find_and_load_unlocked
  File "<frozen importlib._bootstrap>", line 219, in _call_with_frames_removed
  File "<frozen importlib._bootstrap>", line 1006, in _gcd_import
  File "<frozen importlib._bootstrap>", line 983, in _find_and_load
  File "<frozen importlib._bootstrap>", line 965, in _find_and_load_unlocked
ModuleNotFoundError: No module named 'sdk_center'

[2021-04-20T16:31:47+0800] [ERROR] [django.request] [pid:79288] [log.py:228] Internal Server Error: /analysis/query/view
Traceback (most recent call last):
  File "/Users/xiezhaorong/Desktop/my_py/djmyframework/venv/lib/python3.7/site-packages/django/core/handlers/exception.py", line 34, in inner
    response = get_response(request)
  File "/Users/xiezhaorong/Desktop/my_py/djmyframework/venv/lib/python3.7/site-packages/django/core/handlers/base.py", line 115, in _get_response
    response = self.process_exception_by_middleware(e, request)
  File "/Users/xiezhaorong/Desktop/my_py/djmyframework/venv/lib/python3.7/site-packages/django/core/handlers/base.py", line 113, in _get_response
    response = wrapped_callback(request, *callback_args, **callback_kwargs)
  File "/Users/xiezhaorong/Desktop/my_py/djmyframework/djmyframework/apps/analysis/views/query.py", line 232, in query_view
    return render(request,template, locals())
  File "/Users/xiezhaorong/Desktop/my_py/djmyframework/venv/lib/python3.7/site-packages/django/shortcuts.py", line 19, in render
    content = loader.render_to_string(template_name, context, request, using=using)
  File "/Users/xiezhaorong/Desktop/my_py/djmyframework/venv/lib/python3.7/site-packages/django/template/loader.py", line 62, in render_to_string
    return template.render(context, request)
  File "/Users/xiezhaorong/Desktop/my_py/djmyframework/venv/lib/python3.7/site-packages/django/template/backends/jinja2.py", line 71, in render
    return self.template.render(context)
  File "/Users/xiezhaorong/Desktop/my_py/djmyframework/venv/lib/python3.7/site-packages/jinja2/environment.py", line 1090, in render
    self.environment.handle_exception()
  File "/Users/xiezhaorong/Desktop/my_py/djmyframework/venv/lib/python3.7/site-packages/jinja2/environment.py", line 832, in handle_exception
    reraise(*rewrite_traceback_stack(source=source))
  File "/Users/xiezhaorong/Desktop/my_py/djmyframework/venv/lib/python3.7/site-packages/jinja2/_compat.py", line 28, in reraise
    raise value.with_traceback(tb)
  File "/Users/xiezhaorong/Desktop/my_py/djmyframework/djmyframework/jinja2_templates/analysis/query_view.html", line 1, in top-level template code
    {% extends "analysis/base.html" %}
  File "/Users/xiezhaorong/Desktop/my_py/djmyframework/djmyframework/jinja2_templates/analysis/base.html", line 1, in top-level template code
    {% extends "framework/base.html" %}
  File "/Users/xiezhaorong/Desktop/my_py/djmyframework/djmyframework/jinja2_templates/framework/base.html", line 56, in top-level template code
    {% block content %}
  File "/Users/xiezhaorong/Desktop/my_py/djmyframework/djmyframework/jinja2_templates/analysis/query_view.html", line 151, in block "content"
    {% if condition_config and condition_config.get('template') %}
  File "/Users/xiezhaorong/Desktop/my_py/djmyframework/djmyframework/apps/analysis/models/query.py", line 222, in get_context_func
    return import_func(self.mark_map[mark_name]['context_func'])
  File "/Users/xiezhaorong/Desktop/my_py/djmyframework/djmyframework/framework/utils/__init__.py", line 87, in import_func
    return getattr(import_module(module), func)
  File "/Users/xiezhaorong/Desktop/my_py/djmyframework/djmyframework/framework/utils/__init__.py", line 82, in import_module
    return _import_module(name)
  File "/Library/Frameworks/Python.framework/Versions/3.7/lib/python3.7/importlib/__init__.py", line 127, in import_module
    return _bootstrap._gcd_import(name[level:], package, level)
  File "<frozen importlib._bootstrap>", line 1006, in _gcd_import
  File "<frozen importlib._bootstrap>", line 983, in _find_and_load
  File "<frozen importlib._bootstrap>", line 953, in _find_and_load_unlocked
  File "<frozen importlib._bootstrap>", line 219, in _call_with_frames_removed
  File "<frozen importlib._bootstrap>", line 1006, in _gcd_import
  File "<frozen importlib._bootstrap>", line 983, in _find_and_load
  File "<frozen importlib._bootstrap>", line 953, in _find_and_load_unlocked
  File "<frozen importlib._bootstrap>", line 219, in _call_with_frames_removed
  File "<frozen importlib._bootstrap>", line 1006, in _gcd_import
  File "<frozen importlib._bootstrap>", line 983, in _find_and_load
  File "<frozen importlib._bootstrap>", line 965, in _find_and_load_unlocked
ModuleNotFoundError: No module named 'sdk_center'
[2021-04-20T17:20:41+0800] [WARNING] [root] [pid:79370] [middleware.py:81] Traceback (most recent call last):
  File "/Users/xiezhaorong/Desktop/my_py/djmyframework/venv/lib/python3.7/site-packages/django/core/handlers/base.py", line 113, in _get_response
    response = wrapped_callback(request, *callback_args, **callback_kwargs)
  File "/Users/xiezhaorong/Desktop/my_py/djmyframework/djmyframework/apps/analysis/views/statistic.py", line 45, in statistic_list
    from ..models import Server
ImportError: cannot import name 'Server' from 'analysis.models' (/Users/xiezhaorong/Desktop/my_py/djmyframework/djmyframework/apps/analysis/models/__init__.py)

[2021-04-20T17:20:42+0800] [ERROR] [django.request] [pid:79370] [log.py:228] Internal Server Error: /analysis/statistic/list
Traceback (most recent call last):
  File "/Users/xiezhaorong/Desktop/my_py/djmyframework/venv/lib/python3.7/site-packages/django/core/handlers/exception.py", line 34, in inner
    response = get_response(request)
  File "/Users/xiezhaorong/Desktop/my_py/djmyframework/venv/lib/python3.7/site-packages/django/core/handlers/base.py", line 115, in _get_response
    response = self.process_exception_by_middleware(e, request)
  File "/Users/xiezhaorong/Desktop/my_py/djmyframework/venv/lib/python3.7/site-packages/django/core/handlers/base.py", line 113, in _get_response
    response = wrapped_callback(request, *callback_args, **callback_kwargs)
  File "/Users/xiezhaorong/Desktop/my_py/djmyframework/djmyframework/apps/analysis/views/statistic.py", line 45, in statistic_list
    from ..models import Server
ImportError: cannot import name 'Server' from 'analysis.models' (/Users/xiezhaorong/Desktop/my_py/djmyframework/djmyframework/apps/analysis/models/__init__.py)
[2021-04-20T17:20:49+0800] [WARNING] [root] [pid:79370] [middleware.py:81] Traceback (most recent call last):
  File "/Users/xiezhaorong/Desktop/my_py/djmyframework/venv/lib/python3.7/site-packages/django/core/handlers/base.py", line 113, in _get_response
    response = wrapped_callback(request, *callback_args, **callback_kwargs)
  File "/Users/xiezhaorong/Desktop/my_py/djmyframework/djmyframework/apps/analysis/views/statistic.py", line 45, in statistic_list
    from ..models import Server
ImportError: cannot import name 'Server' from 'analysis.models' (/Users/xiezhaorong/Desktop/my_py/djmyframework/djmyframework/apps/analysis/models/__init__.py)

[2021-04-20T17:20:50+0800] [ERROR] [django.request] [pid:79370] [log.py:228] Internal Server Error: /analysis/statistic/list
Traceback (most recent call last):
  File "/Users/xiezhaorong/Desktop/my_py/djmyframework/venv/lib/python3.7/site-packages/django/core/handlers/exception.py", line 34, in inner
    response = get_response(request)
  File "/Users/xiezhaorong/Desktop/my_py/djmyframework/venv/lib/python3.7/site-packages/django/core/handlers/base.py", line 115, in _get_response
    response = self.process_exception_by_middleware(e, request)
  File "/Users/xiezhaorong/Desktop/my_py/djmyframework/venv/lib/python3.7/site-packages/django/core/handlers/base.py", line 113, in _get_response
    response = wrapped_callback(request, *callback_args, **callback_kwargs)
  File "/Users/xiezhaorong/Desktop/my_py/djmyframework/djmyframework/apps/analysis/views/statistic.py", line 45, in statistic_list
    from ..models import Server
ImportError: cannot import name 'Server' from 'analysis.models' (/Users/xiezhaorong/Desktop/my_py/djmyframework/djmyframework/apps/analysis/models/__init__.py)
[2021-04-20T17:26:03+0800] [WARNING] [root] [pid:80158] [middleware.py:81] Traceback (most recent call last):
  File "/Users/xiezhaorong/Desktop/my_py/djmyframework/venv/lib/python3.7/site-packages/django/core/handlers/base.py", line 113, in _get_response
    response = wrapped_callback(request, *callback_args, **callback_kwargs)
  File "/Users/xiezhaorong/Desktop/my_py/djmyframework/djmyframework/apps/analysis/views/statistic.py", line 47, in statistic_list
    list_server = Server.get_server_list()
NameError: name 'Server' is not defined

[2021-04-20T17:26:03+0800] [ERROR] [django.request] [pid:80158] [log.py:228] Internal Server Error: /analysis/statistic/list
Traceback (most recent call last):
  File "/Users/xiezhaorong/Desktop/my_py/djmyframework/venv/lib/python3.7/site-packages/django/core/handlers/exception.py", line 34, in inner
    response = get_response(request)
  File "/Users/xiezhaorong/Desktop/my_py/djmyframework/venv/lib/python3.7/site-packages/django/core/handlers/base.py", line 115, in _get_response
    response = self.process_exception_by_middleware(e, request)
  File "/Users/xiezhaorong/Desktop/my_py/djmyframework/venv/lib/python3.7/site-packages/django/core/handlers/base.py", line 113, in _get_response
    response = wrapped_callback(request, *callback_args, **callback_kwargs)
  File "/Users/xiezhaorong/Desktop/my_py/djmyframework/djmyframework/apps/analysis/views/statistic.py", line 47, in statistic_list
    list_server = Server.get_server_list()
NameError: name 'Server' is not defined
[2021-04-20T17:26:27+0800] [WARNING] [root] [pid:80171] [middleware.py:81] Traceback (most recent call last):
  File "/Users/xiezhaorong/Desktop/my_py/djmyframework/venv/lib/python3.7/site-packages/django/core/handlers/base.py", line 113, in _get_response
    response = wrapped_callback(request, *callback_args, **callback_kwargs)
  File "/Users/xiezhaorong/Desktop/my_py/djmyframework/djmyframework/apps/analysis/views/statistic.py", line 73, in statistic_list
    return render(request,'analysis/statistic_list.html', locals())
  File "/Users/xiezhaorong/Desktop/my_py/djmyframework/venv/lib/python3.7/site-packages/django/shortcuts.py", line 19, in render
    content = loader.render_to_string(template_name, context, request, using=using)
  File "/Users/xiezhaorong/Desktop/my_py/djmyframework/venv/lib/python3.7/site-packages/django/template/loader.py", line 62, in render_to_string
    return template.render(context, request)
  File "/Users/xiezhaorong/Desktop/my_py/djmyframework/venv/lib/python3.7/site-packages/django/template/backends/jinja2.py", line 71, in render
    return self.template.render(context)
  File "/Users/xiezhaorong/Desktop/my_py/djmyframework/venv/lib/python3.7/site-packages/jinja2/environment.py", line 1090, in render
    self.environment.handle_exception()
  File "/Users/xiezhaorong/Desktop/my_py/djmyframework/venv/lib/python3.7/site-packages/jinja2/environment.py", line 832, in handle_exception
    reraise(*rewrite_traceback_stack(source=source))
  File "/Users/xiezhaorong/Desktop/my_py/djmyframework/venv/lib/python3.7/site-packages/jinja2/_compat.py", line 28, in reraise
    raise value.with_traceback(tb)
  File "/Users/xiezhaorong/Desktop/my_py/djmyframework/djmyframework/jinja2_templates/analysis/statistic_list.html", line 1, in top-level template code
    {% extends "old/base.html" %}
  File "/Users/xiezhaorong/Desktop/my_py/djmyframework/djmyframework/jinja2_templates/old/base.html", line 28, in top-level template code
    {% block content %}
  File "/Users/xiezhaorong/Desktop/my_py/djmyframework/djmyframework/jinja2_templates/analysis/statistic_list.html", line 133, in block "content"
    {%include "game_manage/widgets/group_server.html" %}
  File "/Users/xiezhaorong/Desktop/my_py/djmyframework/venv/lib/python3.7/site-packages/jinja2/loaders.py", line 197, in get_source
    raise TemplateNotFound(template)
jinja2.exceptions.TemplateNotFound: game_manage/widgets/group_server.html

[2021-04-20T17:26:28+0800] [ERROR] [django.request] [pid:80171] [log.py:228] Internal Server Error: /analysis/statistic/list
Traceback (most recent call last):
  File "/Users/xiezhaorong/Desktop/my_py/djmyframework/venv/lib/python3.7/site-packages/django/core/handlers/exception.py", line 34, in inner
    response = get_response(request)
  File "/Users/xiezhaorong/Desktop/my_py/djmyframework/venv/lib/python3.7/site-packages/django/core/handlers/base.py", line 115, in _get_response
    response = self.process_exception_by_middleware(e, request)
  File "/Users/xiezhaorong/Desktop/my_py/djmyframework/venv/lib/python3.7/site-packages/django/core/handlers/base.py", line 113, in _get_response
    response = wrapped_callback(request, *callback_args, **callback_kwargs)
  File "/Users/xiezhaorong/Desktop/my_py/djmyframework/djmyframework/apps/analysis/views/statistic.py", line 73, in statistic_list
    return render(request,'analysis/statistic_list.html', locals())
  File "/Users/xiezhaorong/Desktop/my_py/djmyframework/venv/lib/python3.7/site-packages/django/shortcuts.py", line 19, in render
    content = loader.render_to_string(template_name, context, request, using=using)
  File "/Users/xiezhaorong/Desktop/my_py/djmyframework/venv/lib/python3.7/site-packages/django/template/loader.py", line 62, in render_to_string
    return template.render(context, request)
  File "/Users/xiezhaorong/Desktop/my_py/djmyframework/venv/lib/python3.7/site-packages/django/template/backends/jinja2.py", line 71, in render
    return self.template.render(context)
  File "/Users/xiezhaorong/Desktop/my_py/djmyframework/venv/lib/python3.7/site-packages/jinja2/environment.py", line 1090, in render
    self.environment.handle_exception()
  File "/Users/xiezhaorong/Desktop/my_py/djmyframework/venv/lib/python3.7/site-packages/jinja2/environment.py", line 832, in handle_exception
    reraise(*rewrite_traceback_stack(source=source))
  File "/Users/xiezhaorong/Desktop/my_py/djmyframework/venv/lib/python3.7/site-packages/jinja2/_compat.py", line 28, in reraise
    raise value.with_traceback(tb)
  File "/Users/xiezhaorong/Desktop/my_py/djmyframework/djmyframework/jinja2_templates/analysis/statistic_list.html", line 1, in top-level template code
    {% extends "old/base.html" %}
  File "/Users/xiezhaorong/Desktop/my_py/djmyframework/djmyframework/jinja2_templates/old/base.html", line 28, in top-level template code
    {% block content %}
  File "/Users/xiezhaorong/Desktop/my_py/djmyframework/djmyframework/jinja2_templates/analysis/statistic_list.html", line 133, in block "content"
    {%include "game_manage/widgets/group_server.html" %}
  File "/Users/xiezhaorong/Desktop/my_py/djmyframework/venv/lib/python3.7/site-packages/jinja2/loaders.py", line 197, in get_source
    raise TemplateNotFound(template)
jinja2.exceptions.TemplateNotFound: game_manage/widgets/group_server.html
[2021-04-20T17:32:12+0800] [WARNING] [root] [pid:80171] [middleware.py:81] Traceback (most recent call last):
  File "/Users/xiezhaorong/Desktop/my_py/djmyframework/venv/lib/python3.7/site-packages/django/core/handlers/base.py", line 113, in _get_response
    response = wrapped_callback(request, *callback_args, **callback_kwargs)
  File "/Users/xiezhaorong/Desktop/my_py/djmyframework/djmyframework/apps/analysis/views/query.py", line 232, in query_view
    return render(request,template, locals())
  File "/Users/xiezhaorong/Desktop/my_py/djmyframework/venv/lib/python3.7/site-packages/django/shortcuts.py", line 19, in render
    content = loader.render_to_string(template_name, context, request, using=using)
  File "/Users/xiezhaorong/Desktop/my_py/djmyframework/venv/lib/python3.7/site-packages/django/template/loader.py", line 62, in render_to_string
    return template.render(context, request)
  File "/Users/xiezhaorong/Desktop/my_py/djmyframework/venv/lib/python3.7/site-packages/django/template/backends/jinja2.py", line 71, in render
    return self.template.render(context)
  File "/Users/xiezhaorong/Desktop/my_py/djmyframework/venv/lib/python3.7/site-packages/jinja2/environment.py", line 1090, in render
    self.environment.handle_exception()
  File "/Users/xiezhaorong/Desktop/my_py/djmyframework/venv/lib/python3.7/site-packages/jinja2/environment.py", line 832, in handle_exception
    reraise(*rewrite_traceback_stack(source=source))
  File "/Users/xiezhaorong/Desktop/my_py/djmyframework/venv/lib/python3.7/site-packages/jinja2/_compat.py", line 28, in reraise
    raise value.with_traceback(tb)
  File "/Users/xiezhaorong/Desktop/my_py/djmyframework/djmyframework/jinja2_templates/analysis/query_view.html", line 1, in top-level template code
    {% extends "analysis/base.html" %}
  File "/Users/xiezhaorong/Desktop/my_py/djmyframework/djmyframework/jinja2_templates/analysis/base.html", line 1, in top-level template code
    {% extends "framework/base.html" %}
  File "/Users/xiezhaorong/Desktop/my_py/djmyframework/djmyframework/jinja2_templates/framework/base.html", line 56, in top-level template code
    {% block content %}
  File "/Users/xiezhaorong/Desktop/my_py/djmyframework/djmyframework/jinja2_templates/analysis/query_view.html", line 151, in block "content"
    {% if condition_config and condition_config.get('template') %}
  File "/Users/xiezhaorong/Desktop/my_py/djmyframework/djmyframework/apps/analysis/models/query.py", line 222, in get_context_func
    return import_func(self.mark_map[mark_name]['context_func'])
  File "/Users/xiezhaorong/Desktop/my_py/djmyframework/djmyframework/framework/utils/__init__.py", line 87, in import_func
    return getattr(import_module(module), func)
  File "/Users/xiezhaorong/Desktop/my_py/djmyframework/djmyframework/framework/utils/__init__.py", line 82, in import_module
    return _import_module(name)
  File "/Library/Frameworks/Python.framework/Versions/3.7/lib/python3.7/importlib/__init__.py", line 127, in import_module
    return _bootstrap._gcd_import(name[level:], package, level)
  File "<frozen importlib._bootstrap>", line 1006, in _gcd_import
  File "<frozen importlib._bootstrap>", line 983, in _find_and_load
  File "<frozen importlib._bootstrap>", line 953, in _find_and_load_unlocked
  File "<frozen importlib._bootstrap>", line 219, in _call_with_frames_removed
  File "<frozen importlib._bootstrap>", line 1006, in _gcd_import
  File "<frozen importlib._bootstrap>", line 983, in _find_and_load
  File "<frozen importlib._bootstrap>", line 953, in _find_and_load_unlocked
  File "<frozen importlib._bootstrap>", line 219, in _call_with_frames_removed
  File "<frozen importlib._bootstrap>", line 1006, in _gcd_import
  File "<frozen importlib._bootstrap>", line 983, in _find_and_load
  File "<frozen importlib._bootstrap>", line 965, in _find_and_load_unlocked
ModuleNotFoundError: No module named 'sdk_center'

[2021-04-20T17:32:14+0800] [ERROR] [django.request] [pid:80171] [log.py:228] Internal Server Error: /analysis/query/view
Traceback (most recent call last):
  File "/Users/xiezhaorong/Desktop/my_py/djmyframework/venv/lib/python3.7/site-packages/django/core/handlers/exception.py", line 34, in inner
    response = get_response(request)
  File "/Users/xiezhaorong/Desktop/my_py/djmyframework/venv/lib/python3.7/site-packages/django/core/handlers/base.py", line 115, in _get_response
    response = self.process_exception_by_middleware(e, request)
  File "/Users/xiezhaorong/Desktop/my_py/djmyframework/venv/lib/python3.7/site-packages/django/core/handlers/base.py", line 113, in _get_response
    response = wrapped_callback(request, *callback_args, **callback_kwargs)
  File "/Users/xiezhaorong/Desktop/my_py/djmyframework/djmyframework/apps/analysis/views/query.py", line 232, in query_view
    return render(request,template, locals())
  File "/Users/xiezhaorong/Desktop/my_py/djmyframework/venv/lib/python3.7/site-packages/django/shortcuts.py", line 19, in render
    content = loader.render_to_string(template_name, context, request, using=using)
  File "/Users/xiezhaorong/Desktop/my_py/djmyframework/venv/lib/python3.7/site-packages/django/template/loader.py", line 62, in render_to_string
    return template.render(context, request)
  File "/Users/xiezhaorong/Desktop/my_py/djmyframework/venv/lib/python3.7/site-packages/django/template/backends/jinja2.py", line 71, in render
    return self.template.render(context)
  File "/Users/xiezhaorong/Desktop/my_py/djmyframework/venv/lib/python3.7/site-packages/jinja2/environment.py", line 1090, in render
    self.environment.handle_exception()
  File "/Users/xiezhaorong/Desktop/my_py/djmyframework/venv/lib/python3.7/site-packages/jinja2/environment.py", line 832, in handle_exception
    reraise(*rewrite_traceback_stack(source=source))
  File "/Users/xiezhaorong/Desktop/my_py/djmyframework/venv/lib/python3.7/site-packages/jinja2/_compat.py", line 28, in reraise
    raise value.with_traceback(tb)
  File "/Users/xiezhaorong/Desktop/my_py/djmyframework/djmyframework/jinja2_templates/analysis/query_view.html", line 1, in top-level template code
    {% extends "analysis/base.html" %}
  File "/Users/xiezhaorong/Desktop/my_py/djmyframework/djmyframework/jinja2_templates/analysis/base.html", line 1, in top-level template code
    {% extends "framework/base.html" %}
  File "/Users/xiezhaorong/Desktop/my_py/djmyframework/djmyframework/jinja2_templates/framework/base.html", line 56, in top-level template code
    {% block content %}
  File "/Users/xiezhaorong/Desktop/my_py/djmyframework/djmyframework/jinja2_templates/analysis/query_view.html", line 151, in block "content"
    {% if condition_config and condition_config.get('template') %}
  File "/Users/xiezhaorong/Desktop/my_py/djmyframework/djmyframework/apps/analysis/models/query.py", line 222, in get_context_func
    return import_func(self.mark_map[mark_name]['context_func'])
  File "/Users/xiezhaorong/Desktop/my_py/djmyframework/djmyframework/framework/utils/__init__.py", line 87, in import_func
    return getattr(import_module(module), func)
  File "/Users/xiezhaorong/Desktop/my_py/djmyframework/djmyframework/framework/utils/__init__.py", line 82, in import_module
    return _import_module(name)
  File "/Library/Frameworks/Python.framework/Versions/3.7/lib/python3.7/importlib/__init__.py", line 127, in import_module
    return _bootstrap._gcd_import(name[level:], package, level)
  File "<frozen importlib._bootstrap>", line 1006, in _gcd_import
  File "<frozen importlib._bootstrap>", line 983, in _find_and_load
  File "<frozen importlib._bootstrap>", line 953, in _find_and_load_unlocked
  File "<frozen importlib._bootstrap>", line 219, in _call_with_frames_removed
  File "<frozen importlib._bootstrap>", line 1006, in _gcd_import
  File "<frozen importlib._bootstrap>", line 983, in _find_and_load
  File "<frozen importlib._bootstrap>", line 953, in _find_and_load_unlocked
  File "<frozen importlib._bootstrap>", line 219, in _call_with_frames_removed
  File "<frozen importlib._bootstrap>", line 1006, in _gcd_import
  File "<frozen importlib._bootstrap>", line 983, in _find_and_load
  File "<frozen importlib._bootstrap>", line 965, in _find_and_load_unlocked
ModuleNotFoundError: No module named 'sdk_center'
[2021-04-20T17:36:51+0800] [WARNING] [root] [pid:80171] [middleware.py:81] Traceback (most recent call last):
  File "/Users/xiezhaorong/Desktop/my_py/djmyframework/venv/lib/python3.7/site-packages/django/core/handlers/base.py", line 113, in _get_response
    response = wrapped_callback(request, *callback_args, **callback_kwargs)
  File "/Users/xiezhaorong/Desktop/my_py/djmyframework/djmyframework/apps/analysis/views/statistic.py", line 73, in statistic_list
    return render(request,'analysis/statistic_list.html', locals())
  File "/Users/xiezhaorong/Desktop/my_py/djmyframework/venv/lib/python3.7/site-packages/django/shortcuts.py", line 19, in render
    content = loader.render_to_string(template_name, context, request, using=using)
  File "/Users/xiezhaorong/Desktop/my_py/djmyframework/venv/lib/python3.7/site-packages/django/template/loader.py", line 62, in render_to_string
    return template.render(context, request)
  File "/Users/xiezhaorong/Desktop/my_py/djmyframework/venv/lib/python3.7/site-packages/django/template/backends/jinja2.py", line 71, in render
    return self.template.render(context)
  File "/Users/xiezhaorong/Desktop/my_py/djmyframework/venv/lib/python3.7/site-packages/jinja2/environment.py", line 1090, in render
    self.environment.handle_exception()
  File "/Users/xiezhaorong/Desktop/my_py/djmyframework/venv/lib/python3.7/site-packages/jinja2/environment.py", line 832, in handle_exception
    reraise(*rewrite_traceback_stack(source=source))
  File "/Users/xiezhaorong/Desktop/my_py/djmyframework/venv/lib/python3.7/site-packages/jinja2/_compat.py", line 28, in reraise
    raise value.with_traceback(tb)
  File "/Users/xiezhaorong/Desktop/my_py/djmyframework/djmyframework/jinja2_templates/analysis/statistic_list.html", line 1, in top-level template code
    {% extends "analysis/old/base.html" %}
  File "/Users/xiezhaorong/Desktop/my_py/djmyframework/djmyframework/jinja2_templates/analysis/old/base.html", line 31, in top-level template code
    {% include "old/shangxia.html" %}
  File "/Users/xiezhaorong/Desktop/my_py/djmyframework/venv/lib/python3.7/site-packages/jinja2/loaders.py", line 197, in get_source
    raise TemplateNotFound(template)
jinja2.exceptions.TemplateNotFound: old/shangxia.html

[2021-04-20T17:36:52+0800] [ERROR] [django.request] [pid:80171] [log.py:228] Internal Server Error: /analysis/statistic/list
Traceback (most recent call last):
  File "/Users/xiezhaorong/Desktop/my_py/djmyframework/venv/lib/python3.7/site-packages/django/core/handlers/exception.py", line 34, in inner
    response = get_response(request)
  File "/Users/xiezhaorong/Desktop/my_py/djmyframework/venv/lib/python3.7/site-packages/django/core/handlers/base.py", line 115, in _get_response
    response = self.process_exception_by_middleware(e, request)
  File "/Users/xiezhaorong/Desktop/my_py/djmyframework/venv/lib/python3.7/site-packages/django/core/handlers/base.py", line 113, in _get_response
    response = wrapped_callback(request, *callback_args, **callback_kwargs)
  File "/Users/xiezhaorong/Desktop/my_py/djmyframework/djmyframework/apps/analysis/views/statistic.py", line 73, in statistic_list
    return render(request,'analysis/statistic_list.html', locals())
  File "/Users/xiezhaorong/Desktop/my_py/djmyframework/venv/lib/python3.7/site-packages/django/shortcuts.py", line 19, in render
    content = loader.render_to_string(template_name, context, request, using=using)
  File "/Users/xiezhaorong/Desktop/my_py/djmyframework/venv/lib/python3.7/site-packages/django/template/loader.py", line 62, in render_to_string
    return template.render(context, request)
  File "/Users/xiezhaorong/Desktop/my_py/djmyframework/venv/lib/python3.7/site-packages/django/template/backends/jinja2.py", line 71, in render
    return self.template.render(context)
  File "/Users/xiezhaorong/Desktop/my_py/djmyframework/venv/lib/python3.7/site-packages/jinja2/environment.py", line 1090, in render
    self.environment.handle_exception()
  File "/Users/xiezhaorong/Desktop/my_py/djmyframework/venv/lib/python3.7/site-packages/jinja2/environment.py", line 832, in handle_exception
    reraise(*rewrite_traceback_stack(source=source))
  File "/Users/xiezhaorong/Desktop/my_py/djmyframework/venv/lib/python3.7/site-packages/jinja2/_compat.py", line 28, in reraise
    raise value.with_traceback(tb)
  File "/Users/xiezhaorong/Desktop/my_py/djmyframework/djmyframework/jinja2_templates/analysis/statistic_list.html", line 1, in top-level template code
    {% extends "analysis/old/base.html" %}
  File "/Users/xiezhaorong/Desktop/my_py/djmyframework/djmyframework/jinja2_templates/analysis/old/base.html", line 31, in top-level template code
    {% include "old/shangxia.html" %}
  File "/Users/xiezhaorong/Desktop/my_py/djmyframework/venv/lib/python3.7/site-packages/jinja2/loaders.py", line 197, in get_source
    raise TemplateNotFound(template)
jinja2.exceptions.TemplateNotFound: old/shangxia.html
[2021-04-20T17:38:49+0800] [WARNING] [root] [pid:80171] [middleware.py:81] Traceback (most recent call last):
  File "/Users/xiezhaorong/Desktop/my_py/djmyframework/venv/lib/python3.7/site-packages/django/core/handlers/base.py", line 113, in _get_response
    response = wrapped_callback(request, *callback_args, **callback_kwargs)
  File "/Users/xiezhaorong/Desktop/my_py/djmyframework/djmyframework/apps/analysis/views/statistic.py", line 149, in statistic_save
    return render(request,'feedback.html', locals())
  File "/Users/xiezhaorong/Desktop/my_py/djmyframework/venv/lib/python3.7/site-packages/django/shortcuts.py", line 19, in render
    content = loader.render_to_string(template_name, context, request, using=using)
  File "/Users/xiezhaorong/Desktop/my_py/djmyframework/venv/lib/python3.7/site-packages/django/template/loader.py", line 62, in render_to_string
    return template.render(context, request)
  File "/Users/xiezhaorong/Desktop/my_py/djmyframework/venv/lib/python3.7/site-packages/django/template/backends/jinja2.py", line 71, in render
    return self.template.render(context)
  File "/Users/xiezhaorong/Desktop/my_py/djmyframework/venv/lib/python3.7/site-packages/jinja2/environment.py", line 1090, in render
    self.environment.handle_exception()
  File "/Users/xiezhaorong/Desktop/my_py/djmyframework/venv/lib/python3.7/site-packages/jinja2/environment.py", line 832, in handle_exception
    reraise(*rewrite_traceback_stack(source=source))
  File "/Users/xiezhaorong/Desktop/my_py/djmyframework/venv/lib/python3.7/site-packages/jinja2/_compat.py", line 28, in reraise
    raise value.with_traceback(tb)
  File "/Users/xiezhaorong/Desktop/my_py/djmyframework/djmyframework/jinja2_templates/feedback.html", line 1, in top-level template code
    {% extends "old/feedback.html" %}
  File "/Users/xiezhaorong/Desktop/my_py/djmyframework/venv/lib/python3.7/site-packages/jinja2/loaders.py", line 197, in get_source
    raise TemplateNotFound(template)
jinja2.exceptions.TemplateNotFound: old/feedback.html

[2021-04-20T17:38:50+0800] [ERROR] [django.request] [pid:80171] [log.py:228] Internal Server Error: /analysis/statistic/save
Traceback (most recent call last):
  File "/Users/xiezhaorong/Desktop/my_py/djmyframework/venv/lib/python3.7/site-packages/django/core/handlers/exception.py", line 34, in inner
    response = get_response(request)
  File "/Users/xiezhaorong/Desktop/my_py/djmyframework/venv/lib/python3.7/site-packages/django/core/handlers/base.py", line 115, in _get_response
    response = self.process_exception_by_middleware(e, request)
  File "/Users/xiezhaorong/Desktop/my_py/djmyframework/venv/lib/python3.7/site-packages/django/core/handlers/base.py", line 113, in _get_response
    response = wrapped_callback(request, *callback_args, **callback_kwargs)
  File "/Users/xiezhaorong/Desktop/my_py/djmyframework/djmyframework/apps/analysis/views/statistic.py", line 149, in statistic_save
    return render(request,'feedback.html', locals())
  File "/Users/xiezhaorong/Desktop/my_py/djmyframework/venv/lib/python3.7/site-packages/django/shortcuts.py", line 19, in render
    content = loader.render_to_string(template_name, context, request, using=using)
  File "/Users/xiezhaorong/Desktop/my_py/djmyframework/venv/lib/python3.7/site-packages/django/template/loader.py", line 62, in render_to_string
    return template.render(context, request)
  File "/Users/xiezhaorong/Desktop/my_py/djmyframework/venv/lib/python3.7/site-packages/django/template/backends/jinja2.py", line 71, in render
    return self.template.render(context)
  File "/Users/xiezhaorong/Desktop/my_py/djmyframework/venv/lib/python3.7/site-packages/jinja2/environment.py", line 1090, in render
    self.environment.handle_exception()
  File "/Users/xiezhaorong/Desktop/my_py/djmyframework/venv/lib/python3.7/site-packages/jinja2/environment.py", line 832, in handle_exception
    reraise(*rewrite_traceback_stack(source=source))
  File "/Users/xiezhaorong/Desktop/my_py/djmyframework/venv/lib/python3.7/site-packages/jinja2/_compat.py", line 28, in reraise
    raise value.with_traceback(tb)
  File "/Users/xiezhaorong/Desktop/my_py/djmyframework/djmyframework/jinja2_templates/feedback.html", line 1, in top-level template code
    {% extends "old/feedback.html" %}
  File "/Users/xiezhaorong/Desktop/my_py/djmyframework/venv/lib/python3.7/site-packages/jinja2/loaders.py", line 197, in get_source
    raise TemplateNotFound(template)
jinja2.exceptions.TemplateNotFound: old/feedback.html
[2021-04-20T18:06:32+0800] [WARNING] [root] [pid:80171] [middleware.py:81] Traceback (most recent call last):
  File "/Users/xiezhaorong/Desktop/my_py/djmyframework/venv/lib/python3.7/site-packages/django/core/handlers/base.py", line 113, in _get_response
    response = wrapped_callback(request, *callback_args, **callback_kwargs)
  File "/Users/xiezhaorong/Desktop/my_py/djmyframework/djmyframework/apps/analysis/views/query.py", line 232, in query_view
    return render(request,template, locals())
  File "/Users/xiezhaorong/Desktop/my_py/djmyframework/venv/lib/python3.7/site-packages/django/shortcuts.py", line 19, in render
    content = loader.render_to_string(template_name, context, request, using=using)
  File "/Users/xiezhaorong/Desktop/my_py/djmyframework/venv/lib/python3.7/site-packages/django/template/loader.py", line 62, in render_to_string
    return template.render(context, request)
  File "/Users/xiezhaorong/Desktop/my_py/djmyframework/venv/lib/python3.7/site-packages/django/template/backends/jinja2.py", line 71, in render
    return self.template.render(context)
  File "/Users/xiezhaorong/Desktop/my_py/djmyframework/venv/lib/python3.7/site-packages/jinja2/environment.py", line 1090, in render
    self.environment.handle_exception()
  File "/Users/xiezhaorong/Desktop/my_py/djmyframework/venv/lib/python3.7/site-packages/jinja2/environment.py", line 832, in handle_exception
    reraise(*rewrite_traceback_stack(source=source))
  File "/Users/xiezhaorong/Desktop/my_py/djmyframework/venv/lib/python3.7/site-packages/jinja2/_compat.py", line 28, in reraise
    raise value.with_traceback(tb)
  File "/Users/xiezhaorong/Desktop/my_py/djmyframework/djmyframework/jinja2_templates/analysis/query_view.html", line 1, in top-level template code
    {% extends "analysis/base.html" %}
  File "/Users/xiezhaorong/Desktop/my_py/djmyframework/djmyframework/jinja2_templates/analysis/base.html", line 1, in top-level template code
    {% extends "analysis/old/base.html" %}
  File "/Users/xiezhaorong/Desktop/my_py/djmyframework/djmyframework/jinja2_templates/analysis/old/base.html", line 29, in top-level template code
    {% block content %}
  File "/Users/xiezhaorong/Desktop/my_py/djmyframework/djmyframework/jinja2_templates/analysis/query_view.html", line 312, in block "content"
    {% include 'analysis/plugins/export.html' %}
  File "/Users/xiezhaorong/Desktop/my_py/djmyframework/djmyframework/jinja2_templates/analysis/plugins/export.html", line 33, in top-level template code
    {% if is_center_query %}
  File "/Users/xiezhaorong/Desktop/my_py/djmyframework/djmyframework/apps/analysis/models/query.py", line 222, in get_context_func
    return import_func(self.mark_map[mark_name]['context_func'])
  File "/Users/xiezhaorong/Desktop/my_py/djmyframework/djmyframework/framework/utils/__init__.py", line 87, in import_func
    return getattr(import_module(module), func)
  File "/Users/xiezhaorong/Desktop/my_py/djmyframework/djmyframework/framework/utils/__init__.py", line 82, in import_module
    return _import_module(name)
  File "/Library/Frameworks/Python.framework/Versions/3.7/lib/python3.7/importlib/__init__.py", line 127, in import_module
    return _bootstrap._gcd_import(name[level:], package, level)
  File "<frozen importlib._bootstrap>", line 1006, in _gcd_import
  File "<frozen importlib._bootstrap>", line 983, in _find_and_load
  File "<frozen importlib._bootstrap>", line 953, in _find_and_load_unlocked
  File "<frozen importlib._bootstrap>", line 219, in _call_with_frames_removed
  File "<frozen importlib._bootstrap>", line 1006, in _gcd_import
  File "<frozen importlib._bootstrap>", line 983, in _find_and_load
  File "<frozen importlib._bootstrap>", line 953, in _find_and_load_unlocked
  File "<frozen importlib._bootstrap>", line 219, in _call_with_frames_removed
  File "<frozen importlib._bootstrap>", line 1006, in _gcd_import
  File "<frozen importlib._bootstrap>", line 983, in _find_and_load
  File "<frozen importlib._bootstrap>", line 965, in _find_and_load_unlocked
ModuleNotFoundError: No module named 'game_manage'

[2021-04-20T18:06:33+0800] [ERROR] [django.request] [pid:80171] [log.py:228] Internal Server Error: /analysis/query/view
Traceback (most recent call last):
  File "/Users/xiezhaorong/Desktop/my_py/djmyframework/venv/lib/python3.7/site-packages/django/core/handlers/exception.py", line 34, in inner
    response = get_response(request)
  File "/Users/xiezhaorong/Desktop/my_py/djmyframework/venv/lib/python3.7/site-packages/django/core/handlers/base.py", line 115, in _get_response
    response = self.process_exception_by_middleware(e, request)
  File "/Users/xiezhaorong/Desktop/my_py/djmyframework/venv/lib/python3.7/site-packages/django/core/handlers/base.py", line 113, in _get_response
    response = wrapped_callback(request, *callback_args, **callback_kwargs)
  File "/Users/xiezhaorong/Desktop/my_py/djmyframework/djmyframework/apps/analysis/views/query.py", line 232, in query_view
    return render(request,template, locals())
  File "/Users/xiezhaorong/Desktop/my_py/djmyframework/venv/lib/python3.7/site-packages/django/shortcuts.py", line 19, in render
    content = loader.render_to_string(template_name, context, request, using=using)
  File "/Users/xiezhaorong/Desktop/my_py/djmyframework/venv/lib/python3.7/site-packages/django/template/loader.py", line 62, in render_to_string
    return template.render(context, request)
  File "/Users/xiezhaorong/Desktop/my_py/djmyframework/venv/lib/python3.7/site-packages/django/template/backends/jinja2.py", line 71, in render
    return self.template.render(context)
  File "/Users/xiezhaorong/Desktop/my_py/djmyframework/venv/lib/python3.7/site-packages/jinja2/environment.py", line 1090, in render
    self.environment.handle_exception()
  File "/Users/xiezhaorong/Desktop/my_py/djmyframework/venv/lib/python3.7/site-packages/jinja2/environment.py", line 832, in handle_exception
    reraise(*rewrite_traceback_stack(source=source))
  File "/Users/xiezhaorong/Desktop/my_py/djmyframework/venv/lib/python3.7/site-packages/jinja2/_compat.py", line 28, in reraise
    raise value.with_traceback(tb)
  File "/Users/xiezhaorong/Desktop/my_py/djmyframework/djmyframework/jinja2_templates/analysis/query_view.html", line 1, in top-level template code
    {% extends "analysis/base.html" %}
  File "/Users/xiezhaorong/Desktop/my_py/djmyframework/djmyframework/jinja2_templates/analysis/base.html", line 1, in top-level template code
    {% extends "analysis/old/base.html" %}
  File "/Users/xiezhaorong/Desktop/my_py/djmyframework/djmyframework/jinja2_templates/analysis/old/base.html", line 29, in top-level template code
    {% block content %}
  File "/Users/xiezhaorong/Desktop/my_py/djmyframework/djmyframework/jinja2_templates/analysis/query_view.html", line 312, in block "content"
    {% include 'analysis/plugins/export.html' %}
  File "/Users/xiezhaorong/Desktop/my_py/djmyframework/djmyframework/jinja2_templates/analysis/plugins/export.html", line 33, in top-level template code
    {% if is_center_query %}
  File "/Users/xiezhaorong/Desktop/my_py/djmyframework/djmyframework/apps/analysis/models/query.py", line 222, in get_context_func
    return import_func(self.mark_map[mark_name]['context_func'])
  File "/Users/xiezhaorong/Desktop/my_py/djmyframework/djmyframework/framework/utils/__init__.py", line 87, in import_func
    return getattr(import_module(module), func)
  File "/Users/xiezhaorong/Desktop/my_py/djmyframework/djmyframework/framework/utils/__init__.py", line 82, in import_module
    return _import_module(name)
  File "/Library/Frameworks/Python.framework/Versions/3.7/lib/python3.7/importlib/__init__.py", line 127, in import_module
    return _bootstrap._gcd_import(name[level:], package, level)
  File "<frozen importlib._bootstrap>", line 1006, in _gcd_import
  File "<frozen importlib._bootstrap>", line 983, in _find_and_load
  File "<frozen importlib._bootstrap>", line 953, in _find_and_load_unlocked
  File "<frozen importlib._bootstrap>", line 219, in _call_with_frames_removed
  File "<frozen importlib._bootstrap>", line 1006, in _gcd_import
  File "<frozen importlib._bootstrap>", line 983, in _find_and_load
  File "<frozen importlib._bootstrap>", line 953, in _find_and_load_unlocked
  File "<frozen importlib._bootstrap>", line 219, in _call_with_frames_removed
  File "<frozen importlib._bootstrap>", line 1006, in _gcd_import
  File "<frozen importlib._bootstrap>", line 983, in _find_and_load
  File "<frozen importlib._bootstrap>", line 965, in _find_and_load_unlocked
ModuleNotFoundError: No module named 'game_manage'
[2021-04-20T18:06:43+0800] [WARNING] [root] [pid:80171] [middleware.py:81] Traceback (most recent call last):
  File "/Users/xiezhaorong/Desktop/my_py/djmyframework/venv/lib/python3.7/site-packages/django/core/handlers/base.py", line 113, in _get_response
    response = wrapped_callback(request, *callback_args, **callback_kwargs)
  File "/Users/xiezhaorong/Desktop/my_py/djmyframework/djmyframework/apps/analysis/views/query.py", line 232, in query_view
    return render(request,template, locals())
  File "/Users/xiezhaorong/Desktop/my_py/djmyframework/venv/lib/python3.7/site-packages/django/shortcuts.py", line 19, in render
    content = loader.render_to_string(template_name, context, request, using=using)
  File "/Users/xiezhaorong/Desktop/my_py/djmyframework/venv/lib/python3.7/site-packages/django/template/loader.py", line 62, in render_to_string
    return template.render(context, request)
  File "/Users/xiezhaorong/Desktop/my_py/djmyframework/venv/lib/python3.7/site-packages/django/template/backends/jinja2.py", line 71, in render
    return self.template.render(context)
  File "/Users/xiezhaorong/Desktop/my_py/djmyframework/venv/lib/python3.7/site-packages/jinja2/environment.py", line 1090, in render
    self.environment.handle_exception()
  File "/Users/xiezhaorong/Desktop/my_py/djmyframework/venv/lib/python3.7/site-packages/jinja2/environment.py", line 832, in handle_exception
    reraise(*rewrite_traceback_stack(source=source))
  File "/Users/xiezhaorong/Desktop/my_py/djmyframework/venv/lib/python3.7/site-packages/jinja2/_compat.py", line 28, in reraise
    raise value.with_traceback(tb)
  File "/Users/xiezhaorong/Desktop/my_py/djmyframework/djmyframework/jinja2_templates/analysis/query_view.html", line 1, in top-level template code
    {% extends "analysis/base.html" %}
  File "/Users/xiezhaorong/Desktop/my_py/djmyframework/djmyframework/jinja2_templates/analysis/base.html", line 1, in top-level template code
    {% extends "analysis/old/base.html" %}
  File "/Users/xiezhaorong/Desktop/my_py/djmyframework/djmyframework/jinja2_templates/analysis/old/base.html", line 29, in top-level template code
    {% block content %}
  File "/Users/xiezhaorong/Desktop/my_py/djmyframework/djmyframework/jinja2_templates/analysis/query_view.html", line 312, in block "content"
    {% include 'analysis/plugins/export.html' %}
  File "/Users/xiezhaorong/Desktop/my_py/djmyframework/djmyframework/jinja2_templates/analysis/plugins/export.html", line 33, in top-level template code
    {% if is_center_query %}
  File "/Users/xiezhaorong/Desktop/my_py/djmyframework/djmyframework/apps/analysis/models/query.py", line 222, in get_context_func
    return import_func(self.mark_map[mark_name]['context_func'])
  File "/Users/xiezhaorong/Desktop/my_py/djmyframework/djmyframework/framework/utils/__init__.py", line 87, in import_func
    return getattr(import_module(module), func)
  File "/Users/xiezhaorong/Desktop/my_py/djmyframework/djmyframework/framework/utils/__init__.py", line 82, in import_module
    return _import_module(name)
  File "/Library/Frameworks/Python.framework/Versions/3.7/lib/python3.7/importlib/__init__.py", line 127, in import_module
    return _bootstrap._gcd_import(name[level:], package, level)
  File "<frozen importlib._bootstrap>", line 1006, in _gcd_import
  File "<frozen importlib._bootstrap>", line 983, in _find_and_load
  File "<frozen importlib._bootstrap>", line 953, in _find_and_load_unlocked
  File "<frozen importlib._bootstrap>", line 219, in _call_with_frames_removed
  File "<frozen importlib._bootstrap>", line 1006, in _gcd_import
  File "<frozen importlib._bootstrap>", line 983, in _find_and_load
  File "<frozen importlib._bootstrap>", line 953, in _find_and_load_unlocked
  File "<frozen importlib._bootstrap>", line 219, in _call_with_frames_removed
  File "<frozen importlib._bootstrap>", line 1006, in _gcd_import
  File "<frozen importlib._bootstrap>", line 983, in _find_and_load
  File "<frozen importlib._bootstrap>", line 965, in _find_and_load_unlocked
ModuleNotFoundError: No module named 'game_manage'

[2021-04-20T18:06:45+0800] [ERROR] [django.request] [pid:80171] [log.py:228] Internal Server Error: /analysis/query/view
Traceback (most recent call last):
  File "/Users/xiezhaorong/Desktop/my_py/djmyframework/venv/lib/python3.7/site-packages/django/core/handlers/exception.py", line 34, in inner
    response = get_response(request)
  File "/Users/xiezhaorong/Desktop/my_py/djmyframework/venv/lib/python3.7/site-packages/django/core/handlers/base.py", line 115, in _get_response
    response = self.process_exception_by_middleware(e, request)
  File "/Users/xiezhaorong/Desktop/my_py/djmyframework/venv/lib/python3.7/site-packages/django/core/handlers/base.py", line 113, in _get_response
    response = wrapped_callback(request, *callback_args, **callback_kwargs)
  File "/Users/xiezhaorong/Desktop/my_py/djmyframework/djmyframework/apps/analysis/views/query.py", line 232, in query_view
    return render(request,template, locals())
  File "/Users/xiezhaorong/Desktop/my_py/djmyframework/venv/lib/python3.7/site-packages/django/shortcuts.py", line 19, in render
    content = loader.render_to_string(template_name, context, request, using=using)
  File "/Users/xiezhaorong/Desktop/my_py/djmyframework/venv/lib/python3.7/site-packages/django/template/loader.py", line 62, in render_to_string
    return template.render(context, request)
  File "/Users/xiezhaorong/Desktop/my_py/djmyframework/venv/lib/python3.7/site-packages/django/template/backends/jinja2.py", line 71, in render
    return self.template.render(context)
  File "/Users/xiezhaorong/Desktop/my_py/djmyframework/venv/lib/python3.7/site-packages/jinja2/environment.py", line 1090, in render
    self.environment.handle_exception()
  File "/Users/xiezhaorong/Desktop/my_py/djmyframework/venv/lib/python3.7/site-packages/jinja2/environment.py", line 832, in handle_exception
    reraise(*rewrite_traceback_stack(source=source))
  File "/Users/xiezhaorong/Desktop/my_py/djmyframework/venv/lib/python3.7/site-packages/jinja2/_compat.py", line 28, in reraise
    raise value.with_traceback(tb)
  File "/Users/xiezhaorong/Desktop/my_py/djmyframework/djmyframework/jinja2_templates/analysis/query_view.html", line 1, in top-level template code
    {% extends "analysis/base.html" %}
  File "/Users/xiezhaorong/Desktop/my_py/djmyframework/djmyframework/jinja2_templates/analysis/base.html", line 1, in top-level template code
    {% extends "analysis/old/base.html" %}
  File "/Users/xiezhaorong/Desktop/my_py/djmyframework/djmyframework/jinja2_templates/analysis/old/base.html", line 29, in top-level template code
    {% block content %}
  File "/Users/xiezhaorong/Desktop/my_py/djmyframework/djmyframework/jinja2_templates/analysis/query_view.html", line 312, in block "content"
    {% include 'analysis/plugins/export.html' %}
  File "/Users/xiezhaorong/Desktop/my_py/djmyframework/djmyframework/jinja2_templates/analysis/plugins/export.html", line 33, in top-level template code
    {% if is_center_query %}
  File "/Users/xiezhaorong/Desktop/my_py/djmyframework/djmyframework/apps/analysis/models/query.py", line 222, in get_context_func
    return import_func(self.mark_map[mark_name]['context_func'])
  File "/Users/xiezhaorong/Desktop/my_py/djmyframework/djmyframework/framework/utils/__init__.py", line 87, in import_func
    return getattr(import_module(module), func)
  File "/Users/xiezhaorong/Desktop/my_py/djmyframework/djmyframework/framework/utils/__init__.py", line 82, in import_module
    return _import_module(name)
  File "/Library/Frameworks/Python.framework/Versions/3.7/lib/python3.7/importlib/__init__.py", line 127, in import_module
    return _bootstrap._gcd_import(name[level:], package, level)
  File "<frozen importlib._bootstrap>", line 1006, in _gcd_import
  File "<frozen importlib._bootstrap>", line 983, in _find_and_load
  File "<frozen importlib._bootstrap>", line 953, in _find_and_load_unlocked
  File "<frozen importlib._bootstrap>", line 219, in _call_with_frames_removed
  File "<frozen importlib._bootstrap>", line 1006, in _gcd_import
  File "<frozen importlib._bootstrap>", line 983, in _find_and_load
  File "<frozen importlib._bootstrap>", line 953, in _find_and_load_unlocked
  File "<frozen importlib._bootstrap>", line 219, in _call_with_frames_removed
  File "<frozen importlib._bootstrap>", line 1006, in _gcd_import
  File "<frozen importlib._bootstrap>", line 983, in _find_and_load
  File "<frozen importlib._bootstrap>", line 965, in _find_and_load_unlocked
ModuleNotFoundError: No module named 'game_manage'
