[2021-04-12T19:55:45+0800] [WARNING] [root] [pid:88129] [middleware.py:81] Traceback (most recent call last):
  File "/Users/xiezhaorong/Desktop/djmyframework/venv/lib/python3.7/site-packages/django/core/handlers/base.py", line 113, in _get_response
    response = wrapped_callback(request, *callback_args, **callback_kwargs)
  File "/Users/xiezhaorong/Desktop/djmyframework/venv/lib/python3.7/site-packages/django/views/decorators/csrf.py", line 54, in wrapped_view
    return view_func(*args, **kwargs)
  File "/Users/xiezhaorong/Desktop/djmyframework/venv/lib/python3.7/site-packages/rest_framework/viewsets.py", line 125, in view
    return self.dispatch(request, *args, **kwargs)
  File "/Users/xiezhaorong/Desktop/djmyframework/venv/lib/python3.7/site-packages/rest_framework/views.py", line 509, in dispatch
    response = self.handle_exception(exc)
  File "/Users/xiezhaorong/Desktop/djmyframework/venv/lib/python3.7/site-packages/rest_framework/views.py", line 469, in handle_exception
    self.raise_uncaught_exception(exc)
  File "/Users/xiezhaorong/Desktop/djmyframework/venv/lib/python3.7/site-packages/rest_framework/views.py", line 480, in raise_uncaught_exception
    raise exc
  File "/Users/xiezhaorong/Desktop/djmyframework/venv/lib/python3.7/site-packages/rest_framework/views.py", line 506, in dispatch
    response = handler(request, *args, **kwargs)
  File "/Users/xiezhaorong/Desktop/djmyframework/djmyframework/apps/svn_admin/views.py", line 63, in list
    SvnPath.init_svn_projects()
  File "/Users/xiezhaorong/Desktop/djmyframework/djmyframework/apps/svn_admin/models.py", line 155, in init_svn_projects
    project_list = cls.get_svn_project_list()
  File "/Users/xiezhaorong/Desktop/djmyframework/djmyframework/apps/svn_admin/models.py", line 146, in get_svn_project_list
    dirs = os.listdir(SVN_ROOT)
FileNotFoundError: [Errno 2] No such file or directory: '/Users/xzr/Desktop/svn'

[2021-04-12T19:55:45+0800] [ERROR] [django.request] [pid:88129] [log.py:228] Internal Server Error: /svn_admin/svn_path/list
Traceback (most recent call last):
  File "/Users/xiezhaorong/Desktop/djmyframework/venv/lib/python3.7/site-packages/django/core/handlers/exception.py", line 34, in inner
    response = get_response(request)
  File "/Users/xiezhaorong/Desktop/djmyframework/venv/lib/python3.7/site-packages/django/core/handlers/base.py", line 115, in _get_response
    response = self.process_exception_by_middleware(e, request)
  File "/Users/xiezhaorong/Desktop/djmyframework/venv/lib/python3.7/site-packages/django/core/handlers/base.py", line 113, in _get_response
    response = wrapped_callback(request, *callback_args, **callback_kwargs)
  File "/Users/xiezhaorong/Desktop/djmyframework/venv/lib/python3.7/site-packages/django/views/decorators/csrf.py", line 54, in wrapped_view
    return view_func(*args, **kwargs)
  File "/Users/xiezhaorong/Desktop/djmyframework/venv/lib/python3.7/site-packages/rest_framework/viewsets.py", line 125, in view
    return self.dispatch(request, *args, **kwargs)
  File "/Users/xiezhaorong/Desktop/djmyframework/venv/lib/python3.7/site-packages/rest_framework/views.py", line 509, in dispatch
    response = self.handle_exception(exc)
  File "/Users/xiezhaorong/Desktop/djmyframework/venv/lib/python3.7/site-packages/rest_framework/views.py", line 469, in handle_exception
    self.raise_uncaught_exception(exc)
  File "/Users/xiezhaorong/Desktop/djmyframework/venv/lib/python3.7/site-packages/rest_framework/views.py", line 480, in raise_uncaught_exception
    raise exc
  File "/Users/xiezhaorong/Desktop/djmyframework/venv/lib/python3.7/site-packages/rest_framework/views.py", line 506, in dispatch
    response = handler(request, *args, **kwargs)
  File "/Users/xiezhaorong/Desktop/djmyframework/djmyframework/apps/svn_admin/views.py", line 63, in list
    SvnPath.init_svn_projects()
  File "/Users/xiezhaorong/Desktop/djmyframework/djmyframework/apps/svn_admin/models.py", line 155, in init_svn_projects
    project_list = cls.get_svn_project_list()
  File "/Users/xiezhaorong/Desktop/djmyframework/djmyframework/apps/svn_admin/models.py", line 146, in get_svn_project_list
    dirs = os.listdir(SVN_ROOT)
FileNotFoundError: [Errno 2] No such file or directory: '/Users/xzr/Desktop/svn'
[2021-04-12T19:56:06+0800] [WARNING] [root] [pid:88129] [middleware.py:81] Traceback (most recent call last):
  File "/Users/xiezhaorong/Desktop/djmyframework/venv/lib/python3.7/site-packages/django/core/handlers/base.py", line 113, in _get_response
    response = wrapped_callback(request, *callback_args, **callback_kwargs)
  File "/Users/xiezhaorong/Desktop/djmyframework/venv/lib/python3.7/site-packages/django/views/decorators/csrf.py", line 54, in wrapped_view
    return view_func(*args, **kwargs)
  File "/Users/xiezhaorong/Desktop/djmyframework/venv/lib/python3.7/site-packages/rest_framework/viewsets.py", line 125, in view
    return self.dispatch(request, *args, **kwargs)
  File "/Users/xiezhaorong/Desktop/djmyframework/venv/lib/python3.7/site-packages/rest_framework/views.py", line 509, in dispatch
    response = self.handle_exception(exc)
  File "/Users/xiezhaorong/Desktop/djmyframework/venv/lib/python3.7/site-packages/rest_framework/views.py", line 469, in handle_exception
    self.raise_uncaught_exception(exc)
  File "/Users/xiezhaorong/Desktop/djmyframework/venv/lib/python3.7/site-packages/rest_framework/views.py", line 480, in raise_uncaught_exception
    raise exc
  File "/Users/xiezhaorong/Desktop/djmyframework/venv/lib/python3.7/site-packages/rest_framework/views.py", line 506, in dispatch
    response = handler(request, *args, **kwargs)
  File "/Users/xiezhaorong/Desktop/djmyframework/djmyframework/apps/svn_admin/views.py", line 63, in list
    SvnPath.init_svn_projects()
  File "/Users/xiezhaorong/Desktop/djmyframework/djmyframework/apps/svn_admin/models.py", line 155, in init_svn_projects
    project_list = cls.get_svn_project_list()
  File "/Users/xiezhaorong/Desktop/djmyframework/djmyframework/apps/svn_admin/models.py", line 146, in get_svn_project_list
    dirs = os.listdir(SVN_ROOT)
FileNotFoundError: [Errno 2] No such file or directory: '/Users/xzr/Desktop/svn'

[2021-04-12T19:56:06+0800] [ERROR] [django.request] [pid:88129] [log.py:228] Internal Server Error: /svn_admin/svn_path/list
Traceback (most recent call last):
  File "/Users/xiezhaorong/Desktop/djmyframework/venv/lib/python3.7/site-packages/django/core/handlers/exception.py", line 34, in inner
    response = get_response(request)
  File "/Users/xiezhaorong/Desktop/djmyframework/venv/lib/python3.7/site-packages/django/core/handlers/base.py", line 115, in _get_response
    response = self.process_exception_by_middleware(e, request)
  File "/Users/xiezhaorong/Desktop/djmyframework/venv/lib/python3.7/site-packages/django/core/handlers/base.py", line 113, in _get_response
    response = wrapped_callback(request, *callback_args, **callback_kwargs)
  File "/Users/xiezhaorong/Desktop/djmyframework/venv/lib/python3.7/site-packages/django/views/decorators/csrf.py", line 54, in wrapped_view
    return view_func(*args, **kwargs)
  File "/Users/xiezhaorong/Desktop/djmyframework/venv/lib/python3.7/site-packages/rest_framework/viewsets.py", line 125, in view
    return self.dispatch(request, *args, **kwargs)
  File "/Users/xiezhaorong/Desktop/djmyframework/venv/lib/python3.7/site-packages/rest_framework/views.py", line 509, in dispatch
    response = self.handle_exception(exc)
  File "/Users/xiezhaorong/Desktop/djmyframework/venv/lib/python3.7/site-packages/rest_framework/views.py", line 469, in handle_exception
    self.raise_uncaught_exception(exc)
  File "/Users/xiezhaorong/Desktop/djmyframework/venv/lib/python3.7/site-packages/rest_framework/views.py", line 480, in raise_uncaught_exception
    raise exc
  File "/Users/xiezhaorong/Desktop/djmyframework/venv/lib/python3.7/site-packages/rest_framework/views.py", line 506, in dispatch
    response = handler(request, *args, **kwargs)
  File "/Users/xiezhaorong/Desktop/djmyframework/djmyframework/apps/svn_admin/views.py", line 63, in list
    SvnPath.init_svn_projects()
  File "/Users/xiezhaorong/Desktop/djmyframework/djmyframework/apps/svn_admin/models.py", line 155, in init_svn_projects
    project_list = cls.get_svn_project_list()
  File "/Users/xiezhaorong/Desktop/djmyframework/djmyframework/apps/svn_admin/models.py", line 146, in get_svn_project_list
    dirs = os.listdir(SVN_ROOT)
FileNotFoundError: [Errno 2] No such file or directory: '/Users/xzr/Desktop/svn'
[2021-04-12T19:57:04+0800] [WARNING] [root] [pid:88170] [middleware.py:81] Traceback (most recent call last):
  File "/Users/xiezhaorong/Desktop/djmyframework/venv/lib/python3.7/site-packages/django/core/handlers/base.py", line 113, in _get_response
    response = wrapped_callback(request, *callback_args, **callback_kwargs)
  File "/Users/xiezhaorong/Desktop/djmyframework/venv/lib/python3.7/site-packages/django/views/decorators/csrf.py", line 54, in wrapped_view
    return view_func(*args, **kwargs)
  File "/Users/xiezhaorong/Desktop/djmyframework/venv/lib/python3.7/site-packages/rest_framework/viewsets.py", line 125, in view
    return self.dispatch(request, *args, **kwargs)
  File "/Users/xiezhaorong/Desktop/djmyframework/venv/lib/python3.7/site-packages/rest_framework/views.py", line 509, in dispatch
    response = self.handle_exception(exc)
  File "/Users/xiezhaorong/Desktop/djmyframework/venv/lib/python3.7/site-packages/rest_framework/views.py", line 469, in handle_exception
    self.raise_uncaught_exception(exc)
  File "/Users/xiezhaorong/Desktop/djmyframework/venv/lib/python3.7/site-packages/rest_framework/views.py", line 480, in raise_uncaught_exception
    raise exc
  File "/Users/xiezhaorong/Desktop/djmyframework/venv/lib/python3.7/site-packages/rest_framework/views.py", line 506, in dispatch
    response = handler(request, *args, **kwargs)
  File "/Users/xiezhaorong/Desktop/djmyframework/djmyframework/apps/svn_admin/views.py", line 63, in list
    SvnPath.init_svn_projects()
  File "/Users/xiezhaorong/Desktop/djmyframework/djmyframework/apps/svn_admin/models.py", line 155, in init_svn_projects
    project_list = cls.get_svn_project_list()
  File "/Users/xiezhaorong/Desktop/djmyframework/djmyframework/apps/svn_admin/models.py", line 146, in get_svn_project_list
    dirs = os.listdir(SVN_ROOT)
FileNotFoundError: [Errno 2] No such file or directory: '/Users/xiezhaorong/Desktop/djmyframework/djmyframework/svn'

[2021-04-12T19:57:04+0800] [ERROR] [django.request] [pid:88170] [log.py:228] Internal Server Error: /svn_admin/svn_path/list
Traceback (most recent call last):
  File "/Users/xiezhaorong/Desktop/djmyframework/venv/lib/python3.7/site-packages/django/core/handlers/exception.py", line 34, in inner
    response = get_response(request)
  File "/Users/xiezhaorong/Desktop/djmyframework/venv/lib/python3.7/site-packages/django/core/handlers/base.py", line 115, in _get_response
    response = self.process_exception_by_middleware(e, request)
  File "/Users/xiezhaorong/Desktop/djmyframework/venv/lib/python3.7/site-packages/django/core/handlers/base.py", line 113, in _get_response
    response = wrapped_callback(request, *callback_args, **callback_kwargs)
  File "/Users/xiezhaorong/Desktop/djmyframework/venv/lib/python3.7/site-packages/django/views/decorators/csrf.py", line 54, in wrapped_view
    return view_func(*args, **kwargs)
  File "/Users/xiezhaorong/Desktop/djmyframework/venv/lib/python3.7/site-packages/rest_framework/viewsets.py", line 125, in view
    return self.dispatch(request, *args, **kwargs)
  File "/Users/xiezhaorong/Desktop/djmyframework/venv/lib/python3.7/site-packages/rest_framework/views.py", line 509, in dispatch
    response = self.handle_exception(exc)
  File "/Users/xiezhaorong/Desktop/djmyframework/venv/lib/python3.7/site-packages/rest_framework/views.py", line 469, in handle_exception
    self.raise_uncaught_exception(exc)
  File "/Users/xiezhaorong/Desktop/djmyframework/venv/lib/python3.7/site-packages/rest_framework/views.py", line 480, in raise_uncaught_exception
    raise exc
  File "/Users/xiezhaorong/Desktop/djmyframework/venv/lib/python3.7/site-packages/rest_framework/views.py", line 506, in dispatch
    response = handler(request, *args, **kwargs)
  File "/Users/xiezhaorong/Desktop/djmyframework/djmyframework/apps/svn_admin/views.py", line 63, in list
    SvnPath.init_svn_projects()
  File "/Users/xiezhaorong/Desktop/djmyframework/djmyframework/apps/svn_admin/models.py", line 155, in init_svn_projects
    project_list = cls.get_svn_project_list()
  File "/Users/xiezhaorong/Desktop/djmyframework/djmyframework/apps/svn_admin/models.py", line 146, in get_svn_project_list
    dirs = os.listdir(SVN_ROOT)
FileNotFoundError: [Errno 2] No such file or directory: '/Users/xiezhaorong/Desktop/djmyframework/djmyframework/svn'
[2021-04-12T20:02:45+0800] [ERROR] [django.request] [pid:88170] [log.py:228] Internal Server Error: /myadmin/menu/list
Traceback (most recent call last):
  File "/Users/xiezhaorong/Desktop/djmyframework/venv/lib/python3.7/site-packages/django/contrib/sessions/backends/base.py", line 199, in _get_session
    return self._session_cache
AttributeError: 'SessionStore' object has no attribute '_session_cache'

During handling of the above exception, another exception occurred:

Traceback (most recent call last):
  File "/Users/xiezhaorong/Desktop/djmyframework/venv/lib/python3.7/site-packages/pymysql/connections.py", line 732, in _read_bytes
    data = self._rfile.read(num_bytes)
  File "/Library/Frameworks/Python.framework/Versions/3.7/lib/python3.7/socket.py", line 589, in readinto
    return self._sock.recv_into(b)
TimeoutError: [Errno 60] Operation timed out

During handling of the above exception, another exception occurred:

Traceback (most recent call last):
  File "/Users/xiezhaorong/Desktop/djmyframework/venv/lib/python3.7/site-packages/django/db/backends/utils.py", line 86, in _execute
    return self.cursor.execute(sql, params)
  File "/Users/xiezhaorong/Desktop/djmyframework/venv/lib/python3.7/site-packages/django/db/backends/mysql/base.py", line 74, in execute
    return self.cursor.execute(query, args)
  File "/Users/xiezhaorong/Desktop/djmyframework/venv/lib/python3.7/site-packages/pymysql/cursors.py", line 148, in execute
    result = self._query(query)
  File "/Users/xiezhaorong/Desktop/djmyframework/venv/lib/python3.7/site-packages/pymysql/cursors.py", line 310, in _query
    conn.query(q)
  File "/Users/xiezhaorong/Desktop/djmyframework/venv/lib/python3.7/site-packages/pymysql/connections.py", line 548, in query
    self._affected_rows = self._read_query_result(unbuffered=unbuffered)
  File "/Users/xiezhaorong/Desktop/djmyframework/venv/lib/python3.7/site-packages/pymysql/connections.py", line 775, in _read_query_result
    result.read()
  File "/Users/xiezhaorong/Desktop/djmyframework/venv/lib/python3.7/site-packages/pymysql/connections.py", line 1156, in read
    first_packet = self.connection._read_packet()
  File "/Users/xiezhaorong/Desktop/djmyframework/venv/lib/python3.7/site-packages/pymysql/connections.py", line 692, in _read_packet
    packet_header = self._read_bytes(4)
  File "/Users/xiezhaorong/Desktop/djmyframework/venv/lib/python3.7/site-packages/pymysql/connections.py", line 740, in _read_bytes
    "Lost connection to MySQL server during query (%s)" % (e,),
pymysql.err.OperationalError: (2013, 'Lost connection to MySQL server during query ([Errno 60] Operation timed out)')

The above exception was the direct cause of the following exception:

Traceback (most recent call last):
  File "/Users/xiezhaorong/Desktop/djmyframework/venv/lib/python3.7/site-packages/django/core/handlers/exception.py", line 34, in inner
    response = get_response(request)
  File "/Users/xiezhaorong/Desktop/djmyframework/venv/lib/python3.7/site-packages/django/utils/deprecation.py", line 93, in __call__
    response = self.process_request(request)
  File "/Users/xiezhaorong/Desktop/djmyframework/djmyframework/framework/middleware.py", line 37, in process_request
    request.language = request.session.get('_language', '') or request.LANGUAGE_CODE or LANGUAGE_CODE
  File "/Users/xiezhaorong/Desktop/djmyframework/venv/lib/python3.7/site-packages/django/contrib/sessions/backends/base.py", line 75, in get
    return self._session.get(key, default)
  File "/Users/xiezhaorong/Desktop/djmyframework/venv/lib/python3.7/site-packages/django/contrib/sessions/backends/base.py", line 204, in _get_session
    self._session_cache = self.load()
  File "/Users/xiezhaorong/Desktop/djmyframework/venv/lib/python3.7/site-packages/django/contrib/sessions/backends/db.py", line 43, in load
    s = self._get_session_from_db()
  File "/Users/xiezhaorong/Desktop/djmyframework/venv/lib/python3.7/site-packages/django/contrib/sessions/backends/db.py", line 34, in _get_session_from_db
    expire_date__gt=timezone.now()
  File "/Users/xiezhaorong/Desktop/djmyframework/venv/lib/python3.7/site-packages/django/db/models/manager.py", line 82, in manager_method
    return getattr(self.get_queryset(), name)(*args, **kwargs)
  File "/Users/xiezhaorong/Desktop/djmyframework/venv/lib/python3.7/site-packages/django/db/models/query.py", line 411, in get
    num = len(clone)
  File "/Users/xiezhaorong/Desktop/djmyframework/venv/lib/python3.7/site-packages/django/db/models/query.py", line 258, in __len__
    self._fetch_all()
  File "/Users/xiezhaorong/Desktop/djmyframework/venv/lib/python3.7/site-packages/django/db/models/query.py", line 1261, in _fetch_all
    self._result_cache = list(self._iterable_class(self))
  File "/Users/xiezhaorong/Desktop/djmyframework/venv/lib/python3.7/site-packages/django/db/models/query.py", line 57, in __iter__
    results = compiler.execute_sql(chunked_fetch=self.chunked_fetch, chunk_size=self.chunk_size)
  File "/Users/xiezhaorong/Desktop/djmyframework/venv/lib/python3.7/site-packages/django/db/models/sql/compiler.py", line 1154, in execute_sql
    cursor.execute(sql, params)
  File "/Users/xiezhaorong/Desktop/djmyframework/venv/lib/python3.7/site-packages/django/db/backends/utils.py", line 100, in execute
    return super().execute(sql, params)
  File "/Users/xiezhaorong/Desktop/djmyframework/venv/lib/python3.7/site-packages/django/db/backends/utils.py", line 68, in execute
    return self._execute_with_wrappers(sql, params, many=False, executor=self._execute)
  File "/Users/xiezhaorong/Desktop/djmyframework/venv/lib/python3.7/site-packages/django/db/backends/utils.py", line 77, in _execute_with_wrappers
    return executor(sql, params, many, context)
  File "/Users/xiezhaorong/Desktop/djmyframework/venv/lib/python3.7/site-packages/django/db/backends/utils.py", line 86, in _execute
    return self.cursor.execute(sql, params)
  File "/Users/xiezhaorong/Desktop/djmyframework/venv/lib/python3.7/site-packages/django/db/utils.py", line 90, in __exit__
    raise dj_exc_value.with_traceback(traceback) from exc_value
  File "/Users/xiezhaorong/Desktop/djmyframework/venv/lib/python3.7/site-packages/django/db/backends/utils.py", line 86, in _execute
    return self.cursor.execute(sql, params)
  File "/Users/xiezhaorong/Desktop/djmyframework/venv/lib/python3.7/site-packages/django/db/backends/mysql/base.py", line 74, in execute
    return self.cursor.execute(query, args)
  File "/Users/xiezhaorong/Desktop/djmyframework/venv/lib/python3.7/site-packages/pymysql/cursors.py", line 148, in execute
    result = self._query(query)
  File "/Users/xiezhaorong/Desktop/djmyframework/venv/lib/python3.7/site-packages/pymysql/cursors.py", line 310, in _query
    conn.query(q)
  File "/Users/xiezhaorong/Desktop/djmyframework/venv/lib/python3.7/site-packages/pymysql/connections.py", line 548, in query
    self._affected_rows = self._read_query_result(unbuffered=unbuffered)
  File "/Users/xiezhaorong/Desktop/djmyframework/venv/lib/python3.7/site-packages/pymysql/connections.py", line 775, in _read_query_result
    result.read()
  File "/Users/xiezhaorong/Desktop/djmyframework/venv/lib/python3.7/site-packages/pymysql/connections.py", line 1156, in read
    first_packet = self.connection._read_packet()
  File "/Users/xiezhaorong/Desktop/djmyframework/venv/lib/python3.7/site-packages/pymysql/connections.py", line 692, in _read_packet
    packet_header = self._read_bytes(4)
  File "/Users/xiezhaorong/Desktop/djmyframework/venv/lib/python3.7/site-packages/pymysql/connections.py", line 740, in _read_bytes
    "Lost connection to MySQL server during query (%s)" % (e,),
django.db.utils.OperationalError: (2013, 'Lost connection to MySQL server during query ([Errno 60] Operation timed out)')
[2021-04-12T20:02:45+0800] [ERROR] [django.request] [pid:88170] [log.py:228] Internal Server Error: /i18n/js
Traceback (most recent call last):
  File "/Users/xiezhaorong/Desktop/djmyframework/venv/lib/python3.7/site-packages/django/contrib/sessions/backends/base.py", line 199, in _get_session
    return self._session_cache
AttributeError: 'SessionStore' object has no attribute '_session_cache'

During handling of the above exception, another exception occurred:

Traceback (most recent call last):
  File "/Users/xiezhaorong/Desktop/djmyframework/venv/lib/python3.7/site-packages/django/db/backends/utils.py", line 86, in _execute
    return self.cursor.execute(sql, params)
  File "/Users/xiezhaorong/Desktop/djmyframework/venv/lib/python3.7/site-packages/django/db/backends/mysql/base.py", line 74, in execute
    return self.cursor.execute(query, args)
  File "/Users/xiezhaorong/Desktop/djmyframework/venv/lib/python3.7/site-packages/pymysql/cursors.py", line 148, in execute
    result = self._query(query)
  File "/Users/xiezhaorong/Desktop/djmyframework/venv/lib/python3.7/site-packages/pymysql/cursors.py", line 310, in _query
    conn.query(q)
  File "/Users/xiezhaorong/Desktop/djmyframework/venv/lib/python3.7/site-packages/pymysql/connections.py", line 547, in query
    self._execute_command(COMMAND.COM_QUERY, sql)
  File "/Users/xiezhaorong/Desktop/djmyframework/venv/lib/python3.7/site-packages/pymysql/connections.py", line 793, in _execute_command
    raise err.InterfaceError(0, "")
pymysql.err.InterfaceError: (0, '')

The above exception was the direct cause of the following exception:

Traceback (most recent call last):
  File "/Users/xiezhaorong/Desktop/djmyframework/venv/lib/python3.7/site-packages/django/core/handlers/exception.py", line 34, in inner
    response = get_response(request)
  File "/Users/xiezhaorong/Desktop/djmyframework/venv/lib/python3.7/site-packages/django/utils/deprecation.py", line 93, in __call__
    response = self.process_request(request)
  File "/Users/xiezhaorong/Desktop/djmyframework/djmyframework/framework/middleware.py", line 37, in process_request
    request.language = request.session.get('_language', '') or request.LANGUAGE_CODE or LANGUAGE_CODE
  File "/Users/xiezhaorong/Desktop/djmyframework/venv/lib/python3.7/site-packages/django/contrib/sessions/backends/base.py", line 75, in get
    return self._session.get(key, default)
  File "/Users/xiezhaorong/Desktop/djmyframework/venv/lib/python3.7/site-packages/django/contrib/sessions/backends/base.py", line 204, in _get_session
    self._session_cache = self.load()
  File "/Users/xiezhaorong/Desktop/djmyframework/venv/lib/python3.7/site-packages/django/contrib/sessions/backends/db.py", line 43, in load
    s = self._get_session_from_db()
  File "/Users/xiezhaorong/Desktop/djmyframework/venv/lib/python3.7/site-packages/django/contrib/sessions/backends/db.py", line 34, in _get_session_from_db
    expire_date__gt=timezone.now()
  File "/Users/xiezhaorong/Desktop/djmyframework/venv/lib/python3.7/site-packages/django/db/models/manager.py", line 82, in manager_method
    return getattr(self.get_queryset(), name)(*args, **kwargs)
  File "/Users/xiezhaorong/Desktop/djmyframework/venv/lib/python3.7/site-packages/django/db/models/query.py", line 411, in get
    num = len(clone)
  File "/Users/xiezhaorong/Desktop/djmyframework/venv/lib/python3.7/site-packages/django/db/models/query.py", line 258, in __len__
    self._fetch_all()
  File "/Users/xiezhaorong/Desktop/djmyframework/venv/lib/python3.7/site-packages/django/db/models/query.py", line 1261, in _fetch_all
    self._result_cache = list(self._iterable_class(self))
  File "/Users/xiezhaorong/Desktop/djmyframework/venv/lib/python3.7/site-packages/django/db/models/query.py", line 57, in __iter__
    results = compiler.execute_sql(chunked_fetch=self.chunked_fetch, chunk_size=self.chunk_size)
  File "/Users/xiezhaorong/Desktop/djmyframework/venv/lib/python3.7/site-packages/django/db/models/sql/compiler.py", line 1154, in execute_sql
    cursor.execute(sql, params)
  File "/Users/xiezhaorong/Desktop/djmyframework/venv/lib/python3.7/site-packages/django/db/backends/utils.py", line 100, in execute
    return super().execute(sql, params)
  File "/Users/xiezhaorong/Desktop/djmyframework/venv/lib/python3.7/site-packages/django/db/backends/utils.py", line 68, in execute
    return self._execute_with_wrappers(sql, params, many=False, executor=self._execute)
  File "/Users/xiezhaorong/Desktop/djmyframework/venv/lib/python3.7/site-packages/django/db/backends/utils.py", line 77, in _execute_with_wrappers
    return executor(sql, params, many, context)
  File "/Users/xiezhaorong/Desktop/djmyframework/venv/lib/python3.7/site-packages/django/db/backends/utils.py", line 86, in _execute
    return self.cursor.execute(sql, params)
  File "/Users/xiezhaorong/Desktop/djmyframework/venv/lib/python3.7/site-packages/django/db/utils.py", line 90, in __exit__
    raise dj_exc_value.with_traceback(traceback) from exc_value
  File "/Users/xiezhaorong/Desktop/djmyframework/venv/lib/python3.7/site-packages/django/db/backends/utils.py", line 86, in _execute
    return self.cursor.execute(sql, params)
  File "/Users/xiezhaorong/Desktop/djmyframework/venv/lib/python3.7/site-packages/django/db/backends/mysql/base.py", line 74, in execute
    return self.cursor.execute(query, args)
  File "/Users/xiezhaorong/Desktop/djmyframework/venv/lib/python3.7/site-packages/pymysql/cursors.py", line 148, in execute
    result = self._query(query)
  File "/Users/xiezhaorong/Desktop/djmyframework/venv/lib/python3.7/site-packages/pymysql/cursors.py", line 310, in _query
    conn.query(q)
  File "/Users/xiezhaorong/Desktop/djmyframework/venv/lib/python3.7/site-packages/pymysql/connections.py", line 547, in query
    self._execute_command(COMMAND.COM_QUERY, sql)
  File "/Users/xiezhaorong/Desktop/djmyframework/venv/lib/python3.7/site-packages/pymysql/connections.py", line 793, in _execute_command
    raise err.InterfaceError(0, "")
django.db.utils.InterfaceError: (0, '')
